{"comment":"a","date":"2015-11-03 01:39:12+0000","description":"a","lastupdated":"2015-11-03 01:39:12+0000","name":"a","priority":1,"status":0,"id":7}
{"comment":"a","date":"2015-11-02 10:25:02+0000","description":"a","lastupdated":"2015-11-02 10:25:02+0000","name":"a","priority":1,"status":0,"id":0}
Internal Server Error: /ecard/edit_task/
Traceback (most recent call last):
  File "C:\Python27\lib\site-packages\django\core\handlers\base.py", line 132, in get_response
    response = wrapped_callback(request, *callback_args, **callback_kwargs)
  File "C:\Python27\mysite\ecard\views.py", line 69, in edit_task
    date = datetime.strptime(jtask.get('date'), "%Y-%m-%d %H:%M:%S")
  File "C:\Python27\lib\_strptime.py", line 328, in _strptime
    data_string[found.end():])
ValueError: unconverted data remains: +0000
{"comment":"a","date":"2015-11-03 01:39:12+0000","description":"a","lastupdated":"2015-11-03 01:39:12+0000","name":"a","priority":1,"status":0,"id":0}
Internal Server Error: /ecard/edit_task/
Traceback (most recent call last):
  File "C:\Python27\lib\site-packages\django\core\handlers\base.py", line 132, in get_response
    response = wrapped_callback(request, *callback_args, **callback_kwargs)
  File "C:\Python27\mysite\ecard\views.py", line 69, in edit_task
    date = datetime.strptime(jtask.get('date'), "%Y-%m-%d %H:%M:%S")
  File "C:\Python27\lib\_strptime.py", line 328, in _strptime
    data_string[found.end():])
ValueError: unconverted data remains: +0000
Not Found: /favicon.ico
{"comment":"a","date":"2015-11-02 10:25:02+0000","description":"a","lastupdated":"2015-11-02 10:25:02+0000","name":"a","priority":1,"status":0,"id":0}
Internal Server Error: /ecard/edit_task/
Traceback (most recent call last):
  File "C:\Python27\lib\site-packages\django\core\handlers\base.py", line 132, in get_response
    response = wrapped_callback(request, *callback_args, **callback_kwargs)
  File "C:\Python27\mysite\ecard\views.py", line 69, in edit_task
    date = datetime.strptime(jtask.get('date'), "%Y-%m-%d %H:%M:%S")
  File "C:\Python27\lib\_strptime.py", line 328, in _strptime
    data_string[found.end():])
ValueError: unconverted data remains: +0000
{"comment":"a","date":"2015-11-03 01:39:12+0000","description":"a","lastupdated":"2015-11-03 01:39:12+0000","name":"a","priority":1,"status":0,"id":0}
Internal Server Error: /ecard/edit_task/
Traceback (most recent call last):
  File "C:\Python27\lib\site-packages\django\core\handlers\base.py", line 132, in get_response
    response = wrapped_callback(request, *callback_args, **callback_kwargs)
  File "C:\Python27\mysite\ecard\views.py", line 69, in edit_task
    date = datetime.strptime(jtask.get('date'), "%Y-%m-%d %H:%M:%S")
  File "C:\Python27\lib\_strptime.py", line 328, in _strptime
    data_string[found.end():])
ValueError: unconverted data remains: +0000
Internal Server Error: /ecard/delete_task/
Traceback (most recent call last):
  File "C:\Python27\lib\site-packages\django\core\handlers\base.py", line 132, in get_response
    response = wrapped_callback(request, *callback_args, **callback_kwargs)
  File "C:\Python27\mysite\ecard\views.py", line 79, in delete_task
    deleted_task = Task.objects.get(pk=pk)
  File "C:\Python27\lib\site-packages\django\db\models\manager.py", line 127, in manager_method
    return getattr(self.get_queryset(), name)(*args, **kwargs)
  File "C:\Python27\lib\site-packages\django\db\models\query.py", line 334, in get
    self.model._meta.object_name
DoesNotExist: Task matching query does not exist.
{"comment":"a","date":"2015-11-03 01:39:12+0000","description":"a","lastupdated":"2015-11-03 01:39:12+0000","name":"a","priority":1,"status":0,"id":0}
Internal Server Error: /ecard/edit_task/
Traceback (most recent call last):
  File "C:\Python27\lib\site-packages\django\core\handlers\base.py", line 132, in get_response
    response = wrapped_callback(request, *callback_args, **callback_kwargs)
  File "C:\Python27\mysite\ecard\views.py", line 69, in edit_task
    date = datetime.strptime(jtask.get('date'), "%Y-%m-%d %H:%M:%S")
  File "C:\Python27\lib\_strptime.py", line 328, in _strptime
    data_string[found.end():])
ValueError: unconverted data remains: +0000
{"comment":"a","date":"2015-11-03 01:39:12+0000","description":"a","lastupdated":"2015-11-03 01:39:12+0000","name":"a","priority":1,"status":0,"id":0}
Internal Server Error: /ecard/edit_task/
Traceback (most recent call last):
  File "C:\Python27\lib\site-packages\django\core\handlers\base.py", line 132, in get_response
    response = wrapped_callback(request, *callback_args, **callback_kwargs)
  File "C:\Python27\mysite\ecard\views.py", line 70, in edit_task
    last_update= datetime.strptime(jtask.get('lastupdated'), "%Y-%m-%d %H:%M:%S")
  File "C:\Python27\lib\_strptime.py", line 328, in _strptime
    data_string[found.end():])
ValueError: unconverted data remains: +0000
{"comment":"a","date":"2015-11-03 01:39:12+0000","description":"a","lastupdated":"2015-11-03 01:39:12+0000","name":"a","priority":1,"status":0,"id":0}
Internal Server Error: /ecard/edit_task/
Traceback (most recent call last):
  File "C:\Python27\lib\site-packages\django\core\handlers\base.py", line 132, in get_response
    response = wrapped_callback(request, *callback_args, **callback_kwargs)
  File "C:\Python27\mysite\ecard\views.py", line 70, in edit_task
    last_update= datetime.strptime(jtask.get('lastupdated'), "%Y-%m-%d %H:%M:%S")
  File "C:\Python27\lib\_strptime.py", line 328, in _strptime
    data_string[found.end():])
ValueError: unconverted data remains: +0000
{"comment":"a","date":"2015-11-03 01:39:12+0000","description":"a","lastupdated":"2015-11-03 01:39:12+0000","name":"a","priority":1,"status":0,"id":0}
Internal Server Error: /ecard/edit_task/
Traceback (most recent call last):
  File "C:\Python27\lib\site-packages\django\core\handlers\base.py", line 132, in get_response
    response = wrapped_callback(request, *callback_args, **callback_kwargs)
  File "C:\Python27\mysite\ecard\views.py", line 70, in edit_task
    last_update= datetime.strptime(jtask.get('lastupdated'), "%Y-%m-%d %H:%M:%S")
  File "C:\Python27\lib\_strptime.py", line 328, in _strptime
    data_string[found.end():])
ValueError: unconverted data remains: +0000
{"comment":"a","date":"2015-11-03 01:39:12+0000","description":"a","lastupdated":"2015-11-03 01:39:12+0000","name":"a","priority":1,"status":0,"id":0}
Internal Server Error: /ecard/edit_task/
Traceback (most recent call last):
  File "C:\Python27\lib\site-packages\django\core\handlers\base.py", line 132, in get_response
    response = wrapped_callback(request, *callback_args, **callback_kwargs)
  File "C:\Python27\mysite\ecard\views.py", line 70, in edit_task
    last_update= datetime.strptime(jtask.get('lastupdated'), "%Y-%m-%d %H:%M:%S")
  File "C:\Python27\lib\_strptime.py", line 328, in _strptime
    data_string[found.end():])
ValueError: unconverted data remains: +0000
Internal Server Error: /ecard/delete_task/
Traceback (most recent call last):
  File "C:\Python27\lib\site-packages\django\core\handlers\base.py", line 132, in get_response
    response = wrapped_callback(request, *callback_args, **callback_kwargs)
  File "C:\Python27\mysite\ecard\views.py", line 79, in delete_task
    deleted_task = Task.objects.get(pk=pk)
  File "C:\Python27\lib\site-packages\django\db\models\manager.py", line 127, in manager_method
    return getattr(self.get_queryset(), name)(*args, **kwargs)
  File "C:\Python27\lib\site-packages\django\db\models\query.py", line 334, in get
    self.model._meta.object_name
DoesNotExist: Task matching query does not exist.
{"date":"2015-11-02 08:54:05+0000","description":"Go home early, it\u0027s Monday. Working late on the first day of week can lead into really hard week","lastupdated":"2015-11-02 08:54:08+0000","name":"Go home early","priority":2,"status":1,"id":2}
{"date":"2015-11-02 08:54:05+0000","description":"Go home early, it\u0027s Monday. Working late on the first day of week can lead into really hard week","lastupdated":"2015-11-02 08:54:08+0000","name":"Go home early","priority":2,"status":1,"id":3}
Internal Server Error: /ecard/delete_task/
Traceback (most recent call last):
  File "C:\Python27\lib\site-packages\django\core\handlers\base.py", line 132, in get_response
    response = wrapped_callback(request, *callback_args, **callback_kwargs)
  File "C:\Python27\mysite\ecard\views.py", line 79, in delete_task
    deleted_task = Task.objects.get(pk=pk)
  File "C:\Python27\lib\site-packages\django\db\models\manager.py", line 127, in manager_method
    return getattr(self.get_queryset(), name)(*args, **kwargs)
  File "C:\Python27\lib\site-packages\django\db\models\query.py", line 334, in get
    self.model._meta.object_name
DoesNotExist: Task matching query does not exist.
{"date":"2015-11-02 08:55:42+0000","description":"Try to eat healthy food, walking around, drink enough water","lastupdated":"2015-11-02 08:55:42+0000","name":"Be healthy and beautiful","priority":3,"status":1,"id":1}
{"date":"2015-11-02 08:55:42+0000","description":"Try to eat healthy food, walking around, drink enough water","lastupdated":"2015-11-02 08:55:42+0000","name":"Be healthy and beautiful","priority":3,"status":0,"id":10}
{"date":"2015-11-02 08:54:05+0000","description":"Go home early, it\u0027s Monday. Working late on the first day of week can lead into really hard week","lastupdated":"2015-11-02 08:54:08+0000","name":"Go home early","priority":2,"status":0,"id":11}
{"date":"2015-11-02 08:54:05+0000","description":"Go home early, it\u0027s Monday. Working late on the first day of week can lead into really hard week","lastupdated":"2015-11-02 08:54:08+0000","name":"Go home early","priority":2,"status":1,"id":17}
{"comment":"a","date":"2015-11-03 08:29:17+0000","description":"a","lastupdated":"2015-11-03 08:29:17+0000","name":"a","priority":1,"status":0,"id":21}
{"comment":"a","date":"2015-11-03 08:29:17+0000","description":"a","lastupdated":"2015-11-03 08:29:17+0000","name":"a","priority":1,"status":0,"id":0}
Internal Server Error: /ecard/edit_task/
Traceback (most recent call last):
  File "C:\Python27\lib\site-packages\django\core\handlers\base.py", line 132, in get_response
    response = wrapped_callback(request, *callback_args, **callback_kwargs)
  File "C:\Python27\mysite\ecard\views.py", line 72, in edit_task
    new_task.save()
  File "C:\Python27\lib\site-packages\django\db\models\base.py", line 734, in save
    force_update=force_update, update_fields=update_fields)
  File "C:\Python27\lib\site-packages\django\db\models\base.py", line 762, in save_base
    updated = self._save_table(raw, cls, force_insert, force_update, using, update_fields)
  File "C:\Python27\lib\site-packages\django\db\models\base.py", line 846, in _save_table
    result = self._do_insert(cls._base_manager, using, fields, update_pk, raw)
  File "C:\Python27\lib\site-packages\django\db\models\base.py", line 885, in _do_insert
    using=using, raw=raw)
  File "C:\Python27\lib\site-packages\django\db\models\manager.py", line 127, in manager_method
    return getattr(self.get_queryset(), name)(*args, **kwargs)
  File "C:\Python27\lib\site-packages\django\db\models\query.py", line 920, in _insert
    return query.get_compiler(using=using).execute_sql(return_id)
  File "C:\Python27\lib\site-packages\django\db\models\sql\compiler.py", line 973, in execute_sql
    for sql, params in self.as_sql():
  File "C:\Python27\lib\site-packages\django\db\models\sql\compiler.py", line 931, in as_sql
    for obj in self.query.objs
  File "C:\Python27\lib\site-packages\django\db\models\fields\__init__.py", line 710, in get_db_prep_save
    prepared=False)
  File "C:\Python27\lib\site-packages\django\db\models\fields\__init__.py", line 978, in get_db_prep_value
    value = connection.ops.validate_autopk_value(value)
  File "C:\Python27\lib\site-packages\django\db\backends\mysql\operations.py", line 137, in validate_autopk_value
    raise ValueError('The database backend does not accept 0 as a '
ValueError: The database backend does not accept 0 as a value for AutoField.
{"date":"2015-11-03 08:29:17+0000","description":"a","lastupdated":"2015-11-03 08:29:17+0000","name":"a","priority":1,"status":1,"id":24}
{"comment":"a","date":"2015-11-03 08:29:17+0000","description":"a","lastupdated":"2015-11-03 08:29:17+0000","name":"a","priority":1,"status":0,"id":0}
Internal Server Error: /ecard/edit_task/
Traceback (most recent call last):
  File "C:\Python27\lib\site-packages\django\core\handlers\base.py", line 132, in get_response
    response = wrapped_callback(request, *callback_args, **callback_kwargs)
  File "C:\Python27\mysite\ecard\views.py", line 72, in edit_task
    new_task.save()
  File "C:\Python27\lib\site-packages\django\db\models\base.py", line 734, in save
    force_update=force_update, update_fields=update_fields)
  File "C:\Python27\lib\site-packages\django\db\models\base.py", line 762, in save_base
    updated = self._save_table(raw, cls, force_insert, force_update, using, update_fields)
  File "C:\Python27\lib\site-packages\django\db\models\base.py", line 846, in _save_table
    result = self._do_insert(cls._base_manager, using, fields, update_pk, raw)
  File "C:\Python27\lib\site-packages\django\db\models\base.py", line 885, in _do_insert
    using=using, raw=raw)
  File "C:\Python27\lib\site-packages\django\db\models\manager.py", line 127, in manager_method
    return getattr(self.get_queryset(), name)(*args, **kwargs)
  File "C:\Python27\lib\site-packages\django\db\models\query.py", line 920, in _insert
    return query.get_compiler(using=using).execute_sql(return_id)
  File "C:\Python27\lib\site-packages\django\db\models\sql\compiler.py", line 973, in execute_sql
    for sql, params in self.as_sql():
  File "C:\Python27\lib\site-packages\django\db\models\sql\compiler.py", line 931, in as_sql
    for obj in self.query.objs
  File "C:\Python27\lib\site-packages\django\db\models\fields\__init__.py", line 710, in get_db_prep_save
    prepared=False)
  File "C:\Python27\lib\site-packages\django\db\models\fields\__init__.py", line 978, in get_db_prep_value
    value = connection.ops.validate_autopk_value(value)
  File "C:\Python27\lib\site-packages\django\db\backends\mysql\operations.py", line 137, in validate_autopk_value
    raise ValueError('The database backend does not accept 0 as a '
ValueError: The database backend does not accept 0 as a value for AutoField.
{"comment":"a","date":"2015-11-03 08:29:17+0000","description":"a","lastupdated":"2015-11-03 08:29:17+0000","name":"a","priority":1,"status":1,"id":21}
{"comment":"a","date":"2015-11-03 08:29:17+0000","description":"a","lastupdated":"2015-11-03 08:29:17+0000","name":"a","priority":1,"status":1,"id":0}
Internal Server Error: /ecard/edit_task/
Traceback (most recent call last):
  File "C:\Python27\lib\site-packages\django\core\handlers\base.py", line 132, in get_response
    response = wrapped_callback(request, *callback_args, **callback_kwargs)
  File "C:\Python27\mysite\ecard\views.py", line 72, in edit_task
    new_task.save()
  File "C:\Python27\lib\site-packages\django\db\models\base.py", line 734, in save
    force_update=force_update, update_fields=update_fields)
  File "C:\Python27\lib\site-packages\django\db\models\base.py", line 762, in save_base
    updated = self._save_table(raw, cls, force_insert, force_update, using, update_fields)
  File "C:\Python27\lib\site-packages\django\db\models\base.py", line 846, in _save_table
    result = self._do_insert(cls._base_manager, using, fields, update_pk, raw)
  File "C:\Python27\lib\site-packages\django\db\models\base.py", line 885, in _do_insert
    using=using, raw=raw)
  File "C:\Python27\lib\site-packages\django\db\models\manager.py", line 127, in manager_method
    return getattr(self.get_queryset(), name)(*args, **kwargs)
  File "C:\Python27\lib\site-packages\django\db\models\query.py", line 920, in _insert
    return query.get_compiler(using=using).execute_sql(return_id)
  File "C:\Python27\lib\site-packages\django\db\models\sql\compiler.py", line 973, in execute_sql
    for sql, params in self.as_sql():
  File "C:\Python27\lib\site-packages\django\db\models\sql\compiler.py", line 931, in as_sql
    for obj in self.query.objs
  File "C:\Python27\lib\site-packages\django\db\models\fields\__init__.py", line 710, in get_db_prep_save
    prepared=False)
  File "C:\Python27\lib\site-packages\django\db\models\fields\__init__.py", line 978, in get_db_prep_value
    value = connection.ops.validate_autopk_value(value)
  File "C:\Python27\lib\site-packages\django\db\backends\mysql\operations.py", line 137, in validate_autopk_value
    raise ValueError('The database backend does not accept 0 as a '
ValueError: The database backend does not accept 0 as a value for AutoField.
{"date":"2015-11-03 08:29:17+0000","description":"a","lastupdated":"2015-11-03 08:29:17+0000","name":"a","priority":1,"status":0,"id":24}
{"comment":"a","date":"2015-11-03 08:29:17+0000","description":"a","lastupdated":"2015-11-03 08:29:17+0000","name":"a","priority":1,"status":1,"id":0}
Internal Server Error: /ecard/edit_task/
Traceback (most recent call last):
  File "C:\Python27\lib\site-packages\django\core\handlers\base.py", line 132, in get_response
    response = wrapped_callback(request, *callback_args, **callback_kwargs)
  File "C:\Python27\mysite\ecard\views.py", line 72, in edit_task
    new_task.save()
  File "C:\Python27\lib\site-packages\django\db\models\base.py", line 734, in save
    force_update=force_update, update_fields=update_fields)
  File "C:\Python27\lib\site-packages\django\db\models\base.py", line 762, in save_base
    updated = self._save_table(raw, cls, force_insert, force_update, using, update_fields)
  File "C:\Python27\lib\site-packages\django\db\models\base.py", line 846, in _save_table
    result = self._do_insert(cls._base_manager, using, fields, update_pk, raw)
  File "C:\Python27\lib\site-packages\django\db\models\base.py", line 885, in _do_insert
    using=using, raw=raw)
  File "C:\Python27\lib\site-packages\django\db\models\manager.py", line 127, in manager_method
    return getattr(self.get_queryset(), name)(*args, **kwargs)
  File "C:\Python27\lib\site-packages\django\db\models\query.py", line 920, in _insert
    return query.get_compiler(using=using).execute_sql(return_id)
  File "C:\Python27\lib\site-packages\django\db\models\sql\compiler.py", line 973, in execute_sql
    for sql, params in self.as_sql():
  File "C:\Python27\lib\site-packages\django\db\models\sql\compiler.py", line 931, in as_sql
    for obj in self.query.objs
  File "C:\Python27\lib\site-packages\django\db\models\fields\__init__.py", line 710, in get_db_prep_save
    prepared=False)
  File "C:\Python27\lib\site-packages\django\db\models\fields\__init__.py", line 978, in get_db_prep_value
    value = connection.ops.validate_autopk_value(value)
  File "C:\Python27\lib\site-packages\django\db\backends\mysql\operations.py", line 137, in validate_autopk_value
    raise ValueError('The database backend does not accept 0 as a '
ValueError: The database backend does not accept 0 as a value for AutoField.
{"date":"2015-11-03 08:29:17+0000","description":"a","lastupdated":"2015-11-03 08:29:17+0000","name":"a","priority":1,"status":1,"id":24}
{"comment":"a","date":"2015-11-03 08:29:17+0000","description":"a","lastupdated":"2015-11-03 08:29:17+0000","name":"a","priority":1,"status":1,"id":0}
Internal Server Error: /ecard/edit_task/
Traceback (most recent call last):
  File "C:\Python27\lib\site-packages\django\core\handlers\base.py", line 132, in get_response
    response = wrapped_callback(request, *callback_args, **callback_kwargs)
  File "C:\Python27\mysite\ecard\views.py", line 72, in edit_task
    new_task.save()
  File "C:\Python27\lib\site-packages\django\db\models\base.py", line 734, in save
    force_update=force_update, update_fields=update_fields)
  File "C:\Python27\lib\site-packages\django\db\models\base.py", line 762, in save_base
    updated = self._save_table(raw, cls, force_insert, force_update, using, update_fields)
  File "C:\Python27\lib\site-packages\django\db\models\base.py", line 846, in _save_table
    result = self._do_insert(cls._base_manager, using, fields, update_pk, raw)
  File "C:\Python27\lib\site-packages\django\db\models\base.py", line 885, in _do_insert
    using=using, raw=raw)
  File "C:\Python27\lib\site-packages\django\db\models\manager.py", line 127, in manager_method
    return getattr(self.get_queryset(), name)(*args, **kwargs)
  File "C:\Python27\lib\site-packages\django\db\models\query.py", line 920, in _insert
    return query.get_compiler(using=using).execute_sql(return_id)
  File "C:\Python27\lib\site-packages\django\db\models\sql\compiler.py", line 973, in execute_sql
    for sql, params in self.as_sql():
  File "C:\Python27\lib\site-packages\django\db\models\sql\compiler.py", line 931, in as_sql
    for obj in self.query.objs
  File "C:\Python27\lib\site-packages\django\db\models\fields\__init__.py", line 710, in get_db_prep_save
    prepared=False)
  File "C:\Python27\lib\site-packages\django\db\models\fields\__init__.py", line 978, in get_db_prep_value
    value = connection.ops.validate_autopk_value(value)
  File "C:\Python27\lib\site-packages\django\db\backends\mysql\operations.py", line 137, in validate_autopk_value
    raise ValueError('The database backend does not accept 0 as a '
ValueError: The database backend does not accept 0 as a value for AutoField.
{"comment":"b","date":"2015-11-03 08:30:18+0000","description":"b","lastupdated":"2015-11-03 08:30:18+0000","name":"b","priority":1,"status":0,"id":34}
{"comment":"a","date":"2015-11-03 08:29:17+0000","description":"a","lastupdated":"2015-11-03 08:29:17+0000","name":"a","priority":1,"status":1,"id":0}
Internal Server Error: /ecard/edit_task/
Traceback (most recent call last):
  File "C:\Python27\lib\site-packages\django\core\handlers\base.py", line 132, in get_response
    response = wrapped_callback(request, *callback_args, **callback_kwargs)
  File "C:\Python27\mysite\ecard\views.py", line 72, in edit_task
    new_task.save()
  File "C:\Python27\lib\site-packages\django\db\models\base.py", line 734, in save
    force_update=force_update, update_fields=update_fields)
  File "C:\Python27\lib\site-packages\django\db\models\base.py", line 762, in save_base
    updated = self._save_table(raw, cls, force_insert, force_update, using, update_fields)
  File "C:\Python27\lib\site-packages\django\db\models\base.py", line 846, in _save_table
    result = self._do_insert(cls._base_manager, using, fields, update_pk, raw)
  File "C:\Python27\lib\site-packages\django\db\models\base.py", line 885, in _do_insert
    using=using, raw=raw)
  File "C:\Python27\lib\site-packages\django\db\models\manager.py", line 127, in manager_method
    return getattr(self.get_queryset(), name)(*args, **kwargs)
  File "C:\Python27\lib\site-packages\django\db\models\query.py", line 920, in _insert
    return query.get_compiler(using=using).execute_sql(return_id)
  File "C:\Python27\lib\site-packages\django\db\models\sql\compiler.py", line 973, in execute_sql
    for sql, params in self.as_sql():
  File "C:\Python27\lib\site-packages\django\db\models\sql\compiler.py", line 931, in as_sql
    for obj in self.query.objs
  File "C:\Python27\lib\site-packages\django\db\models\fields\__init__.py", line 710, in get_db_prep_save
    prepared=False)
  File "C:\Python27\lib\site-packages\django\db\models\fields\__init__.py", line 978, in get_db_prep_value
    value = connection.ops.validate_autopk_value(value)
  File "C:\Python27\lib\site-packages\django\db\backends\mysql\operations.py", line 137, in validate_autopk_value
    raise ValueError('The database backend does not accept 0 as a '
ValueError: The database backend does not accept 0 as a value for AutoField.
{"comment":"b","date":"2015-11-03 08:30:18+0000","description":"b","lastupdated":"2015-11-03 08:30:18+0000","name":"b","priority":1,"status":0,"id":0}
Internal Server Error: /ecard/edit_task/
Traceback (most recent call last):
  File "C:\Python27\lib\site-packages\django\core\handlers\base.py", line 132, in get_response
    response = wrapped_callback(request, *callback_args, **callback_kwargs)
  File "C:\Python27\mysite\ecard\views.py", line 72, in edit_task
    new_task.save()
  File "C:\Python27\lib\site-packages\django\db\models\base.py", line 734, in save
    force_update=force_update, update_fields=update_fields)
  File "C:\Python27\lib\site-packages\django\db\models\base.py", line 762, in save_base
    updated = self._save_table(raw, cls, force_insert, force_update, using, update_fields)
  File "C:\Python27\lib\site-packages\django\db\models\base.py", line 846, in _save_table
    result = self._do_insert(cls._base_manager, using, fields, update_pk, raw)
  File "C:\Python27\lib\site-packages\django\db\models\base.py", line 885, in _do_insert
    using=using, raw=raw)
  File "C:\Python27\lib\site-packages\django\db\models\manager.py", line 127, in manager_method
    return getattr(self.get_queryset(), name)(*args, **kwargs)
  File "C:\Python27\lib\site-packages\django\db\models\query.py", line 920, in _insert
    return query.get_compiler(using=using).execute_sql(return_id)
  File "C:\Python27\lib\site-packages\django\db\models\sql\compiler.py", line 973, in execute_sql
    for sql, params in self.as_sql():
  File "C:\Python27\lib\site-packages\django\db\models\sql\compiler.py", line 931, in as_sql
    for obj in self.query.objs
  File "C:\Python27\lib\site-packages\django\db\models\fields\__init__.py", line 710, in get_db_prep_save
    prepared=False)
  File "C:\Python27\lib\site-packages\django\db\models\fields\__init__.py", line 978, in get_db_prep_value
    value = connection.ops.validate_autopk_value(value)
  File "C:\Python27\lib\site-packages\django\db\backends\mysql\operations.py", line 137, in validate_autopk_value
    raise ValueError('The database backend does not accept 0 as a '
ValueError: The database backend does not accept 0 as a value for AutoField.
{"comment":"a","date":"2015-11-04 08:33:44+0000","description":"a","lastupdated":"2015-11-04 08:33:44+0000","name":"a","priority":1,"status":0,"id":38}
{"comment":"vvv","date":"2015-11-05 08:36:12+0000","description":"vvv","lastupdated":"2015-11-05 08:36:12+0000","name":"vvv","priority":1,"status":0,"id":40}
{"comment":"xxxxxx","date":"2015-11-06 08:43:50+0000","description":"xxxxxx","lastupdated":"2015-11-06 08:43:50+0000","name":"xxxxxx","priority":1,"status":0,"id":42}
{"comment":"a","date":"2015-11-03 08:46:44+0000","description":"a","lastupdated":"2015-11-03 08:46:44+0000","name":"a","priority":1,"status":0,"id":1}
{"comment":"a","date":"2015-11-03 08:53:34+0000","description":"a","lastupdated":"2015-11-03 08:53:34+0000","name":"a","priority":1,"status":0,"id":1}
{"comment":"a","date":"2015-11-03 08:58:56+0000","description":"a","lastupdated":"2015-11-03 08:58:56+0000","name":"a","priority":1,"status":0,"id":1}
{"comment":"la la la","date":"2015-11-04 04:31:18+0000","description":"I love my house","lastupdated":"2015-11-04 04:31:18+0000","name":"Go home early","priority":1,"status":0}
{"date":"2015-11-04 04:31:18+0000","description":"I love my house","id":"2","lastupdated":"2015-11-04 04:31:18+0000","name":"Go home early","priority":1,"status":1}
{"date":"2015-11-04 04:31:18+0000","description":"I love my house","id":"2","lastupdated":"2015-11-04 04:31:18+0000","name":"Go home early","priority":1,"status":1}
Not Found: /favicon.ico
{"date":"2015-11-04 04:31:18+0000","description":"I love my house","id":"2","lastupdated":"2015-11-04 04:31:18+0000","name":"Go home early","priority":1,"status":1}
{"date":"2015-11-04 04:31:18+0000","description":"I love my house","id":"3","lastupdated":"2015-11-04 04:31:18+0000","name":"Go home early","priority":1,"status":0}
{"comment":"","date":"2015-11-03 08:58:56+0000","description":"haha","id":"1","lastupdated":"2015-11-03 08:58:56+0000","name":"wtf","priority":1,"status":0}
{"date":"2015-11-03 08:58:56+0000","description":"haha","id":"1","lastupdated":"2015-11-03 08:58:56+0000","name":"wtf","priority":1,"status":1}
{"date":"2015-11-04 04:31:18+0000","description":"I love my house","id":"4","lastupdated":"2015-11-04 04:31:18+0000","name":"Go home early","priority":1,"status":0}
{"comment":"I\u0027ve done  this","date":"2015-11-04 10:18:30+0000","description":"Draw a commit to keep momentum for my projects","lastupdated":"2015-11-04 10:18:30+0000","name":"Draw a commit","priority":1,"status":0}
{"comment":"","date":"2015-11-05 10:19:46+0000","description":"Keep your health, Go home early and walk around. Remember to turn off your wifi","lastupdated":"2015-11-05 10:19:46+0000","name":"Go home early","priority":2,"status":0}
{"date":"2015-11-04 10:18:30+0000","description":"Draw a commit to keep momentum for my projects","id":"5","lastupdated":"2015-11-04 10:18:30+0000","name":"Draw a commit","priority":1,"status":1}
{"comment":"","date":"2015-11-05 10:26:48+0000","description":"Close your eye and mediate for just 2 minutes. Love your window of soul!","lastupdated":"2015-11-05 10:26:48+0000","name":"Mediation","priority":1,"status":0}
Not Found: /favicon.ico
Not Found: /favicon.ico
Not Found: /favicon.ico
Internal Server Error: /ecard/edit_book/
Traceback (most recent call last):
  File "C:\Python27\lib\site-packages\django\core\handlers\base.py", line 132, in get_response
    response = wrapped_callback(request, *callback_args, **callback_kwargs)
  File "C:\Python27\mysite\ecard\views.py", line 41, in edit_book
    return add_book(request)
  File "C:\Python27\mysite\ecard\views.py", line 46, in add_book
    jbook = json.loads(new_book_string);
  File "C:\Python27\lib\json\__init__.py", line 310, in loads
    return _default_decoder.decode(s)
  File "C:\Python27\lib\json\decoder.py", line 346, in decode
    obj, end = self.raw_decode(s, idx=_w(s, 0).end())
  File "C:\Python27\lib\json\decoder.py", line 364, in raw_decode
    raise ValueError("No JSON object could be decoded")
ValueError: No JSON object could be decoded
Internal Server Error: /ecard/edit_book/
Traceback (most recent call last):
  File "C:\Python27\lib\site-packages\django\core\handlers\base.py", line 132, in get_response
    response = wrapped_callback(request, *callback_args, **callback_kwargs)
  File "C:\Python27\mysite\ecard\views.py", line 41, in edit_book
    return add_book(request)
  File "C:\Python27\mysite\ecard\views.py", line 46, in add_book
    jbook = json.loads(new_book_string);
  File "C:\Python27\lib\json\__init__.py", line 310, in loads
    return _default_decoder.decode(s)
  File "C:\Python27\lib\json\decoder.py", line 346, in decode
    obj, end = self.raw_decode(s, idx=_w(s, 0).end())
  File "C:\Python27\lib\json\decoder.py", line 364, in raw_decode
    raise ValueError("No JSON object could be decoded")
ValueError: No JSON object could be decoded
Internal Server Error: /ecard/edit_book/
Traceback (most recent call last):
  File "C:\Python27\lib\site-packages\django\core\handlers\base.py", line 132, in get_response
    response = wrapped_callback(request, *callback_args, **callback_kwargs)
  File "C:\Python27\mysite\ecard\views.py", line 41, in edit_book
    return add_book(request)
  File "C:\Python27\mysite\ecard\views.py", line 46, in add_book
    jbook = json.loads(new_book_string);
  File "C:\Python27\lib\json\__init__.py", line 310, in loads
    return _default_decoder.decode(s)
  File "C:\Python27\lib\json\decoder.py", line 346, in decode
    obj, end = self.raw_decode(s, idx=_w(s, 0).end())
  File "C:\Python27\lib\json\decoder.py", line 364, in raw_decode
    raise ValueError("No JSON object could be decoded")
ValueError: No JSON object could be decoded
Internal Server Error: /ecard/edit_book/
Traceback (most recent call last):
  File "C:\Python27\lib\site-packages\django\core\handlers\base.py", line 132, in get_response
    response = wrapped_callback(request, *callback_args, **callback_kwargs)
  File "C:\Python27\mysite\ecard\views.py", line 41, in edit_book
    return add_book(request)
  File "C:\Python27\mysite\ecard\views.py", line 46, in add_book
    jbook = json.loads(new_book_string);
  File "C:\Python27\lib\json\__init__.py", line 310, in loads
    return _default_decoder.decode(s)
  File "C:\Python27\lib\json\decoder.py", line 346, in decode
    obj, end = self.raw_decode(s, idx=_w(s, 0).end())
  File "C:\Python27\lib\json\decoder.py", line 364, in raw_decode
    raise ValueError("No JSON object could be decoded")
ValueError: No JSON object could be decoded
Internal Server Error: /ecard/edit_book/
Traceback (most recent call last):
  File "C:\Python27\lib\site-packages\django\core\handlers\base.py", line 132, in get_response
    response = wrapped_callback(request, *callback_args, **callback_kwargs)
  File "C:\Python27\mysite\ecard\views.py", line 41, in edit_book
    return add_book(request)
  File "C:\Python27\mysite\ecard\views.py", line 46, in add_book
    jbook = json.loads(new_book_string);
  File "C:\Python27\lib\json\__init__.py", line 310, in loads
    return _default_decoder.decode(s)
  File "C:\Python27\lib\json\decoder.py", line 346, in decode
    obj, end = self.raw_decode(s, idx=_w(s, 0).end())
  File "C:\Python27\lib\json\decoder.py", line 364, in raw_decode
    raise ValueError("No JSON object could be decoded")
ValueError: No JSON object could be decoded
Internal Server Error: /ecard/edit_book/
Traceback (most recent call last):
  File "C:\Python27\lib\site-packages\django\core\handlers\base.py", line 132, in get_response
    response = wrapped_callback(request, *callback_args, **callback_kwargs)
  File "C:\Python27\mysite\ecard\views.py", line 41, in edit_book
    return add_book(request)
  File "C:\Python27\mysite\ecard\views.py", line 46, in add_book
    jbook = json.loads(new_book_string);
  File "C:\Python27\lib\json\__init__.py", line 310, in loads
    return _default_decoder.decode(s)
  File "C:\Python27\lib\json\decoder.py", line 346, in decode
    obj, end = self.raw_decode(s, idx=_w(s, 0).end())
  File "C:\Python27\lib\json\decoder.py", line 364, in raw_decode
    raise ValueError("No JSON object could be decoded")
ValueError: No JSON object could be decoded
Internal Server Error: /ecard/edit_book/
Traceback (most recent call last):
  File "C:\Python27\lib\site-packages\django\core\handlers\base.py", line 132, in get_response
    response = wrapped_callback(request, *callback_args, **callback_kwargs)
  File "C:\Python27\mysite\ecard\views.py", line 41, in edit_book
    return add_book(request)
  File "C:\Python27\mysite\ecard\views.py", line 46, in add_book
    jbook = json.loads(new_book_string);
  File "C:\Python27\lib\json\__init__.py", line 310, in loads
    return _default_decoder.decode(s)
  File "C:\Python27\lib\json\decoder.py", line 346, in decode
    obj, end = self.raw_decode(s, idx=_w(s, 0).end())
  File "C:\Python27\lib\json\decoder.py", line 364, in raw_decode
    raise ValueError("No JSON object could be decoded")
ValueError: No JSON object could be decoded
Internal Server Error: /ecard/edit_book/
Traceback (most recent call last):
  File "C:\Python27\lib\site-packages\django\core\handlers\base.py", line 132, in get_response
    response = wrapped_callback(request, *callback_args, **callback_kwargs)
  File "C:\Python27\mysite\ecard\views.py", line 41, in edit_book
    return add_book(request)
  File "C:\Python27\mysite\ecard\views.py", line 46, in add_book
    jbook = json.loads(new_book_string);
  File "C:\Python27\lib\json\__init__.py", line 310, in loads
    return _default_decoder.decode(s)
  File "C:\Python27\lib\json\decoder.py", line 346, in decode
    obj, end = self.raw_decode(s, idx=_w(s, 0).end())
  File "C:\Python27\lib\json\decoder.py", line 364, in raw_decode
    raise ValueError("No JSON object could be decoded")
ValueError: No JSON object could be decoded
Internal Server Error: /ecard/edit_book/
Traceback (most recent call last):
  File "C:\Python27\lib\site-packages\django\core\handlers\base.py", line 132, in get_response
    response = wrapped_callback(request, *callback_args, **callback_kwargs)
  File "C:\Python27\mysite\ecard\views.py", line 41, in edit_book
    return add_book(request)
  File "C:\Python27\mysite\ecard\views.py", line 46, in add_book
    jbook = json.loads(new_book_string);
  File "C:\Python27\lib\json\__init__.py", line 310, in loads
    return _default_decoder.decode(s)
  File "C:\Python27\lib\json\decoder.py", line 346, in decode
    obj, end = self.raw_decode(s, idx=_w(s, 0).end())
  File "C:\Python27\lib\json\decoder.py", line 364, in raw_decode
    raise ValueError("No JSON object could be decoded")
ValueError: No JSON object could be decoded
Internal Server Error: /ecard/edit_book/
Traceback (most recent call last):
  File "C:\Python27\lib\site-packages\django\core\handlers\base.py", line 132, in get_response
    response = wrapped_callback(request, *callback_args, **callback_kwargs)
  File "C:\Python27\mysite\ecard\views.py", line 41, in edit_book
    return add_book(request)
  File "C:\Python27\mysite\ecard\views.py", line 46, in add_book
    jbook = json.loads(new_book_string);
  File "C:\Python27\lib\json\__init__.py", line 310, in loads
    return _default_decoder.decode(s)
  File "C:\Python27\lib\json\decoder.py", line 346, in decode
    obj, end = self.raw_decode(s, idx=_w(s, 0).end())
  File "C:\Python27\lib\json\decoder.py", line 364, in raw_decode
    raise ValueError("No JSON object could be decoded")
ValueError: No JSON object could be decoded
Internal Server Error: /ecard/edit_book/
Traceback (most recent call last):
  File "C:\Python27\lib\site-packages\django\core\handlers\base.py", line 132, in get_response
    response = wrapped_callback(request, *callback_args, **callback_kwargs)
  File "C:\Python27\mysite\ecard\views.py", line 41, in edit_book
    return add_book(request)
  File "C:\Python27\mysite\ecard\views.py", line 46, in add_book
    jbook = json.loads(new_book_string);
  File "C:\Python27\lib\json\__init__.py", line 310, in loads
    return _default_decoder.decode(s)
  File "C:\Python27\lib\json\decoder.py", line 346, in decode
    obj, end = self.raw_decode(s, idx=_w(s, 0).end())
  File "C:\Python27\lib\json\decoder.py", line 364, in raw_decode
    raise ValueError("No JSON object could be decoded")
ValueError: No JSON object could be decoded
Internal Server Error: /ecard/edit_book/
Traceback (most recent call last):
  File "C:\Python27\lib\site-packages\django\core\handlers\base.py", line 132, in get_response
    response = wrapped_callback(request, *callback_args, **callback_kwargs)
  File "C:\Python27\mysite\ecard\views.py", line 41, in edit_book
    return add_book(request)
  File "C:\Python27\mysite\ecard\views.py", line 46, in add_book
    jbook = json.loads(new_book_string);
  File "C:\Python27\lib\json\__init__.py", line 310, in loads
    return _default_decoder.decode(s)
  File "C:\Python27\lib\json\decoder.py", line 346, in decode
    obj, end = self.raw_decode(s, idx=_w(s, 0).end())
  File "C:\Python27\lib\json\decoder.py", line 364, in raw_decode
    raise ValueError("No JSON object could be decoded")
ValueError: No JSON object could be decoded
Internal Server Error: /ecard/edit_book/
Traceback (most recent call last):
  File "C:\Python27\lib\site-packages\django\core\handlers\base.py", line 132, in get_response
    response = wrapped_callback(request, *callback_args, **callback_kwargs)
  File "C:\Python27\mysite\ecard\views.py", line 41, in edit_book
    return add_book(request)
  File "C:\Python27\mysite\ecard\views.py", line 46, in add_book
    jbook = json.loads(new_book_string);
  File "C:\Python27\lib\json\__init__.py", line 310, in loads
    return _default_decoder.decode(s)
  File "C:\Python27\lib\json\decoder.py", line 346, in decode
    obj, end = self.raw_decode(s, idx=_w(s, 0).end())
  File "C:\Python27\lib\json\decoder.py", line 364, in raw_decode
    raise ValueError("No JSON object could be decoded")
ValueError: No JSON object could be decoded
Internal Server Error: /ecard/edit_book/
Traceback (most recent call last):
  File "C:\Python27\lib\site-packages\django\core\handlers\base.py", line 132, in get_response
    response = wrapped_callback(request, *callback_args, **callback_kwargs)
  File "C:\Python27\mysite\ecard\views.py", line 41, in edit_book
    return add_book(request)
  File "C:\Python27\mysite\ecard\views.py", line 46, in add_book
    jbook = json.loads(new_book_string);
  File "C:\Python27\lib\json\__init__.py", line 310, in loads
    return _default_decoder.decode(s)
  File "C:\Python27\lib\json\decoder.py", line 346, in decode
    obj, end = self.raw_decode(s, idx=_w(s, 0).end())
  File "C:\Python27\lib\json\decoder.py", line 364, in raw_decode
    raise ValueError("No JSON object could be decoded")
ValueError: No JSON object could be decoded
Internal Server Error: /ecard/edit_book/
Traceback (most recent call last):
  File "C:\Python27\lib\site-packages\django\core\handlers\base.py", line 132, in get_response
    response = wrapped_callback(request, *callback_args, **callback_kwargs)
  File "C:\Python27\mysite\ecard\views.py", line 41, in edit_book
    return add_book(request)
  File "C:\Python27\mysite\ecard\views.py", line 46, in add_book
    jbook = json.loads(new_book_string);
  File "C:\Python27\lib\json\__init__.py", line 310, in loads
    return _default_decoder.decode(s)
  File "C:\Python27\lib\json\decoder.py", line 346, in decode
    obj, end = self.raw_decode(s, idx=_w(s, 0).end())
  File "C:\Python27\lib\json\decoder.py", line 364, in raw_decode
    raise ValueError("No JSON object could be decoded")
ValueError: No JSON object could be decoded
Internal Server Error: /ecard/edit_book/
Traceback (most recent call last):
  File "C:\Python27\lib\site-packages\django\core\handlers\base.py", line 132, in get_response
    response = wrapped_callback(request, *callback_args, **callback_kwargs)
  File "C:\Python27\mysite\ecard\views.py", line 41, in edit_book
    return add_book(request)
  File "C:\Python27\mysite\ecard\views.py", line 46, in add_book
    jbook = json.loads(new_book_string);
  File "C:\Python27\lib\json\__init__.py", line 310, in loads
    return _default_decoder.decode(s)
  File "C:\Python27\lib\json\decoder.py", line 346, in decode
    obj, end = self.raw_decode(s, idx=_w(s, 0).end())
  File "C:\Python27\lib\json\decoder.py", line 364, in raw_decode
    raise ValueError("No JSON object could be decoded")
ValueError: No JSON object could be decoded
Internal Server Error: /ecard/edit_book/
Traceback (most recent call last):
  File "C:\Python27\lib\site-packages\django\core\handlers\base.py", line 132, in get_response
    response = wrapped_callback(request, *callback_args, **callback_kwargs)
  File "C:\Python27\mysite\ecard\views.py", line 41, in edit_book
    return add_book(request)
  File "C:\Python27\mysite\ecard\views.py", line 46, in add_book
    jbook = json.loads(new_book_string);
  File "C:\Python27\lib\json\__init__.py", line 310, in loads
    return _default_decoder.decode(s)
  File "C:\Python27\lib\json\decoder.py", line 346, in decode
    obj, end = self.raw_decode(s, idx=_w(s, 0).end())
  File "C:\Python27\lib\json\decoder.py", line 364, in raw_decode
    raise ValueError("No JSON object could be decoded")
ValueError: No JSON object could be decoded
Internal Server Error: /ecard/edit_book/
Traceback (most recent call last):
  File "C:\Python27\lib\site-packages\django\core\handlers\base.py", line 132, in get_response
    response = wrapped_callback(request, *callback_args, **callback_kwargs)
  File "C:\Python27\mysite\ecard\views.py", line 41, in edit_book
    return add_book(request)
  File "C:\Python27\mysite\ecard\views.py", line 46, in add_book
    jbook = json.loads(new_book_string);
  File "C:\Python27\lib\json\__init__.py", line 310, in loads
    return _default_decoder.decode(s)
  File "C:\Python27\lib\json\decoder.py", line 346, in decode
    obj, end = self.raw_decode(s, idx=_w(s, 0).end())
  File "C:\Python27\lib\json\decoder.py", line 364, in raw_decode
    raise ValueError("No JSON object could be decoded")
ValueError: No JSON object could be decoded
Internal Server Error: /ecard/edit_book/
Traceback (most recent call last):
  File "C:\Python27\lib\site-packages\django\core\handlers\base.py", line 132, in get_response
    response = wrapped_callback(request, *callback_args, **callback_kwargs)
  File "C:\Python27\mysite\ecard\views.py", line 41, in edit_book
    return add_book(request)
  File "C:\Python27\mysite\ecard\views.py", line 46, in add_book
    jbook = json.loads(new_book_string);
  File "C:\Python27\lib\json\__init__.py", line 310, in loads
    return _default_decoder.decode(s)
  File "C:\Python27\lib\json\decoder.py", line 346, in decode
    obj, end = self.raw_decode(s, idx=_w(s, 0).end())
  File "C:\Python27\lib\json\decoder.py", line 364, in raw_decode
    raise ValueError("No JSON object could be decoded")
ValueError: No JSON object could be decoded
Internal Server Error: /ecard/edit_book/
Traceback (most recent call last):
  File "C:\Python27\lib\site-packages\django\core\handlers\base.py", line 132, in get_response
    response = wrapped_callback(request, *callback_args, **callback_kwargs)
  File "C:\Python27\mysite\ecard\views.py", line 41, in edit_book
    return add_book(request)
  File "C:\Python27\mysite\ecard\views.py", line 46, in add_book
    jbook = json.loads(new_book_string);
  File "C:\Python27\lib\json\__init__.py", line 310, in loads
    return _default_decoder.decode(s)
  File "C:\Python27\lib\json\decoder.py", line 346, in decode
    obj, end = self.raw_decode(s, idx=_w(s, 0).end())
  File "C:\Python27\lib\json\decoder.py", line 364, in raw_decode
    raise ValueError("No JSON object could be decoded")
ValueError: No JSON object could be decoded
Internal Server Error: /ecard/edit_book/
Traceback (most recent call last):
  File "C:\Python27\lib\site-packages\django\core\handlers\base.py", line 132, in get_response
    response = wrapped_callback(request, *callback_args, **callback_kwargs)
  File "C:\Python27\mysite\ecard\views.py", line 41, in edit_book
    return add_book(request)
  File "C:\Python27\mysite\ecard\views.py", line 47, in add_book
    updated_book = Book(pk=jbook.get("id"), name=jbook.get("name"), iconUrl=jbook.get("iconUrl"), author=jbook.get("author"),vocabulary=jbook.get("vocabulary"),comment=jbook.get("comment"),booklink=jbook.get("booklink"),mood=jbook.get("mood"))
  File "C:\Python27\lib\site-packages\django\db\models\base.py", line 468, in __init__
    setattr(self, field.name, rel_obj)
  File "C:\Python27\lib\site-packages\django\db\models\fields\related.py", line 621, in __set__
    (instance._meta.object_name, self.field.name)
ValueError: Cannot assign None: "Book.booklink" does not allow null values.
Internal Server Error: /ecard/get_unfinished_tasks/
Traceback (most recent call last):
  File "C:\Python27\lib\site-packages\django\core\handlers\base.py", line 119, in get_response
    resolver_match = resolver.resolve(request.path_info)
  File "C:\Python27\lib\site-packages\django\core\urlresolvers.py", line 365, in resolve
    for pattern in self.url_patterns:
  File "C:\Python27\lib\site-packages\django\core\urlresolvers.py", line 401, in url_patterns
    patterns = getattr(self.urlconf_module, "urlpatterns", self.urlconf_module)
  File "C:\Python27\lib\site-packages\django\core\urlresolvers.py", line 395, in urlconf_module
    self._urlconf_module = import_module(self.urlconf_name)
  File "C:\Python27\lib\importlib\__init__.py", line 37, in import_module
    __import__(name)
  File "C:\Python27\mysite\mysite\urls.py", line 20, in <module>
    url(r'^ecard/', include('ecard.urls')),
  File "C:\Python27\lib\site-packages\django\conf\urls\__init__.py", line 33, in include
    urlconf_module = import_module(urlconf_module)
  File "C:\Python27\lib\importlib\__init__.py", line 37, in import_module
    __import__(name)
  File "C:\Python27\mysite\ecard\urls.py", line 3, in <module>
    from . import views
  File "C:\Python27\mysite\ecard\views.py", line 51
    link = new Link(url="http://google.com.vn")
                  ^
SyntaxError: invalid syntax
Internal Server Error: /ecard/get_books/
Traceback (most recent call last):
  File "C:\Python27\lib\site-packages\django\core\handlers\base.py", line 119, in get_response
    resolver_match = resolver.resolve(request.path_info)
  File "C:\Python27\lib\site-packages\django\core\urlresolvers.py", line 365, in resolve
    for pattern in self.url_patterns:
  File "C:\Python27\lib\site-packages\django\core\urlresolvers.py", line 401, in url_patterns
    patterns = getattr(self.urlconf_module, "urlpatterns", self.urlconf_module)
  File "C:\Python27\lib\site-packages\django\core\urlresolvers.py", line 395, in urlconf_module
    self._urlconf_module = import_module(self.urlconf_name)
  File "C:\Python27\lib\importlib\__init__.py", line 37, in import_module
    __import__(name)
  File "C:\Python27\mysite\mysite\urls.py", line 20, in <module>
    url(r'^ecard/', include('ecard.urls')),
  File "C:\Python27\lib\site-packages\django\conf\urls\__init__.py", line 33, in include
    urlconf_module = import_module(urlconf_module)
  File "C:\Python27\lib\importlib\__init__.py", line 37, in import_module
    __import__(name)
  File "C:\Python27\mysite\ecard\urls.py", line 3, in <module>
    from . import views
  File "C:\Python27\mysite\ecard\views.py", line 51
    link = new Link(url="http://google.com.vn")
                  ^
SyntaxError: invalid syntax
Internal Server Error: /ecard/get_unfinished_tasks/
Traceback (most recent call last):
  File "C:\Python27\lib\site-packages\django\core\handlers\base.py", line 119, in get_response
    resolver_match = resolver.resolve(request.path_info)
  File "C:\Python27\lib\site-packages\django\core\urlresolvers.py", line 365, in resolve
    for pattern in self.url_patterns:
  File "C:\Python27\lib\site-packages\django\core\urlresolvers.py", line 401, in url_patterns
    patterns = getattr(self.urlconf_module, "urlpatterns", self.urlconf_module)
  File "C:\Python27\lib\site-packages\django\core\urlresolvers.py", line 395, in urlconf_module
    self._urlconf_module = import_module(self.urlconf_name)
  File "C:\Python27\lib\importlib\__init__.py", line 37, in import_module
    __import__(name)
  File "C:\Python27\mysite\mysite\urls.py", line 20, in <module>
    url(r'^ecard/', include('ecard.urls')),
  File "C:\Python27\lib\site-packages\django\conf\urls\__init__.py", line 33, in include
    urlconf_module = import_module(urlconf_module)
  File "C:\Python27\lib\importlib\__init__.py", line 37, in import_module
    __import__(name)
  File "C:\Python27\mysite\ecard\urls.py", line 3, in <module>
    from . import views
  File "C:\Python27\mysite\ecard\views.py", line 51
    link = new Link(url="http://google.com.vn")
                  ^
SyntaxError: invalid syntax
Internal Server Error: /ecard/get_books/
Traceback (most recent call last):
  File "C:\Python27\lib\site-packages\django\core\handlers\base.py", line 119, in get_response
    resolver_match = resolver.resolve(request.path_info)
  File "C:\Python27\lib\site-packages\django\core\urlresolvers.py", line 365, in resolve
    for pattern in self.url_patterns:
  File "C:\Python27\lib\site-packages\django\core\urlresolvers.py", line 401, in url_patterns
    patterns = getattr(self.urlconf_module, "urlpatterns", self.urlconf_module)
  File "C:\Python27\lib\site-packages\django\core\urlresolvers.py", line 395, in urlconf_module
    self._urlconf_module = import_module(self.urlconf_name)
  File "C:\Python27\lib\importlib\__init__.py", line 37, in import_module
    __import__(name)
  File "C:\Python27\mysite\mysite\urls.py", line 20, in <module>
    url(r'^ecard/', include('ecard.urls')),
  File "C:\Python27\lib\site-packages\django\conf\urls\__init__.py", line 33, in include
    urlconf_module = import_module(urlconf_module)
  File "C:\Python27\lib\importlib\__init__.py", line 37, in import_module
    __import__(name)
  File "C:\Python27\mysite\ecard\urls.py", line 3, in <module>
    from . import views
  File "C:\Python27\mysite\ecard\views.py", line 51
    link = new Link(url="http://google.com.vn")
                  ^
SyntaxError: invalid syntax
Internal Server Error: /ecard/get_books/
Traceback (most recent call last):
  File "C:\Python27\lib\site-packages\django\core\handlers\base.py", line 119, in get_response
    resolver_match = resolver.resolve(request.path_info)
  File "C:\Python27\lib\site-packages\django\core\urlresolvers.py", line 365, in resolve
    for pattern in self.url_patterns:
  File "C:\Python27\lib\site-packages\django\core\urlresolvers.py", line 401, in url_patterns
    patterns = getattr(self.urlconf_module, "urlpatterns", self.urlconf_module)
  File "C:\Python27\lib\site-packages\django\core\urlresolvers.py", line 395, in urlconf_module
    self._urlconf_module = import_module(self.urlconf_name)
  File "C:\Python27\lib\importlib\__init__.py", line 37, in import_module
    __import__(name)
  File "C:\Python27\mysite\mysite\urls.py", line 20, in <module>
    url(r'^ecard/', include('ecard.urls')),
  File "C:\Python27\lib\site-packages\django\conf\urls\__init__.py", line 33, in include
    urlconf_module = import_module(urlconf_module)
  File "C:\Python27\lib\importlib\__init__.py", line 37, in import_module
    __import__(name)
  File "C:\Python27\mysite\ecard\urls.py", line 3, in <module>
    from . import views
  File "C:\Python27\mysite\ecard\views.py", line 51
    link = new Link(url="http://google.com.vn")
                  ^
SyntaxError: invalid syntax
Not Found: /favicon.ico
Not Found: /favicon.ico
Internal Server Error: /ecard/edit_book/
Traceback (most recent call last):
  File "/usr/local/lib/python2.7/dist-packages/django/core/handlers/base.py", line 132, in get_response
    response = wrapped_callback(request, *callback_args, **callback_kwargs)
  File "/home/vietnguyen/mysite/ecard/views.py", line 41, in edit_book
    return add_book(request)
  File "/home/vietnguyen/mysite/ecard/views.py", line 47, in add_book
    old_book = Book.objects.get(pk=jbook.get("id"))
  File "/usr/local/lib/python2.7/dist-packages/django/db/models/manager.py", line 127, in manager_method
    return getattr(self.get_queryset(), name)(*args, **kwargs)
  File "/usr/local/lib/python2.7/dist-packages/django/db/models/query.py", line 334, in get
    self.model._meta.object_name
DoesNotExist: Book matching query does not exist.
{"author":"Louis Sachar","comment":"Really my first english book. I remember reading them with difficulty thanks to my bad english by then. I read it on my ipad.","iconUrl":"https://upload.wikimedia.org/wikipedia/en/c/c3/Sachar_-_Holes_Coverart.png","link":"https://en.wikipedia.org/wiki/Holes_%28novel%29","mood":"Fate love kind child","name":"Holes","vocabulary":"aaa,shovel,lizard,crate,donkey,reptile,odor,onion,"}
Internal Server Error: /ecard/edit_book/
Traceback (most recent call last):
  File "/usr/local/lib/python2.7/dist-packages/django/core/handlers/base.py", line 132, in get_response
    response = wrapped_callback(request, *callback_args, **callback_kwargs)
  File "/home/vietnguyen/mysite/ecard/views.py", line 41, in edit_book
    return add_book(request)
  File "/home/vietnguyen/mysite/ecard/views.py", line 47, in add_book
    old_book = Book.objects.get(pk=jbook.get("id"))
  File "/usr/local/lib/python2.7/dist-packages/django/db/models/manager.py", line 127, in manager_method
    return getattr(self.get_queryset(), name)(*args, **kwargs)
  File "/usr/local/lib/python2.7/dist-packages/django/db/models/query.py", line 334, in get
    self.model._meta.object_name
DoesNotExist: Book matching query does not exist.
{"author":"Louis Sachar","comment":"Really my first english book. I remember reading them with difficulty thanks to my bad english by then. I read it on my ipad.","iconUrl":"https://upload.wikimedia.org/wikipedia/en/c/c3/Sachar_-_Holes_Coverart.png","link":"https://en.wikipedia.org/wiki/Holes_%28novel%29","mood":"Fate love kind child","name":"Holes","vocabulary":"bbb,aaa,shovel,lizard,crate,donkey,reptile,odor,onion,"}
Internal Server Error: /ecard/edit_book/
Traceback (most recent call last):
  File "/usr/local/lib/python2.7/dist-packages/django/core/handlers/base.py", line 132, in get_response
    response = wrapped_callback(request, *callback_args, **callback_kwargs)
  File "/home/vietnguyen/mysite/ecard/views.py", line 41, in edit_book
    return add_book(request)
  File "/home/vietnguyen/mysite/ecard/views.py", line 47, in add_book
    old_book = Book.objects.get(pk=jbook.get("id"))
  File "/usr/local/lib/python2.7/dist-packages/django/db/models/manager.py", line 127, in manager_method
    return getattr(self.get_queryset(), name)(*args, **kwargs)
  File "/usr/local/lib/python2.7/dist-packages/django/db/models/query.py", line 334, in get
    self.model._meta.object_name
DoesNotExist: Book matching query does not exist.
{"author":"Louis Sachar","comment":"Really my first english book. I remember reading them with difficulty thanks to my bad english by then. I read it on my ipad.","iconUrl":"https://upload.wikimedia.org/wikipedia/en/c/c3/Sachar_-_Holes_Coverart.png","link":"https://en.wikipedia.org/wiki/Holes_%28novel%29","mood":"Fate love kind child","name":"Holes","vocabulary":"aaa,shovel,lizard,crate,donkey,reptile,odor,onion,"}
Internal Server Error: /ecard/edit_book/
Traceback (most recent call last):
  File "/usr/local/lib/python2.7/dist-packages/django/core/handlers/base.py", line 132, in get_response
    response = wrapped_callback(request, *callback_args, **callback_kwargs)
  File "/home/vietnguyen/mysite/ecard/views.py", line 41, in edit_book
    return add_book(request)
  File "/home/vietnguyen/mysite/ecard/views.py", line 47, in add_book
    old_book = Book.objects.get(pk=jbook.get("id"))
  File "/usr/local/lib/python2.7/dist-packages/django/db/models/manager.py", line 127, in manager_method
    return getattr(self.get_queryset(), name)(*args, **kwargs)
  File "/usr/local/lib/python2.7/dist-packages/django/db/models/query.py", line 334, in get
    self.model._meta.object_name
DoesNotExist: Book matching query does not exist.
{"author":"Cynthia Rylant","comment":"Short, light story about family love. \"Summer\", \"May\", \"Ob\", \"Cletus\" were beautiful names","iconUrl":"https://upload.wikimedia.org/wikipedia/en/thumb/e/e9/Missing_May.jpg/220px-Missing_May.jpg","link":"https://en.wikipedia.org/wiki/Missing_May","mood":"Love your loveones","name":"Missing May","vocabulary":"aaa,trailer,consolation,hoist,sharpnel,thigh,twig,snap"}
Internal Server Error: /ecard/edit_book/
Traceback (most recent call last):
  File "/usr/local/lib/python2.7/dist-packages/django/core/handlers/base.py", line 132, in get_response
    response = wrapped_callback(request, *callback_args, **callback_kwargs)
  File "/home/vietnguyen/mysite/ecard/views.py", line 41, in edit_book
    return add_book(request)
  File "/home/vietnguyen/mysite/ecard/views.py", line 47, in add_book
    old_book = Book.objects.get(pk=jbook.get("id"))
  File "/usr/local/lib/python2.7/dist-packages/django/db/models/manager.py", line 127, in manager_method
    return getattr(self.get_queryset(), name)(*args, **kwargs)
  File "/usr/local/lib/python2.7/dist-packages/django/db/models/query.py", line 334, in get
    self.model._meta.object_name
DoesNotExist: Book matching query does not exist.
{"author":"Khaled Hosseini","comment":"Some kind of shocking feeling. I have a first look at some remote lands like Afgha","iconUrl":"https://upload.wikimedia.org/wikipedia/en/thumb/6/62/Kite_runner.jpg/220px-Kite_runner.jpg","link":"https://en.wikipedia.org/wiki/The_Kite_Runner","mood":"Life is full of stunning story","name":"The Kite Runner","vocabulary":"crisp[aaa],breeze,vault,intricate,mosaic,creek (noun,water),elope,congenital,perpetually,polio,mold(the world),acne,gruff,coarse,abundantly,shred,bleak,toss,hurl,valiant,impeccable,mischief,seduce,scramble,weep,bead,bolt,flank,refrain,snicker,tuck, armpit,ironic,crunch,thaw,covet,trot,scuttle,adjacent,flush ( ~blush),shierk,gnarle,havoc, discard,thwart,limp,mumble,motto,slaughter"}
Internal Server Error: /ecard/edit_book/
Traceback (most recent call last):
  File "/usr/local/lib/python2.7/dist-packages/django/core/handlers/base.py", line 132, in get_response
    response = wrapped_callback(request, *callback_args, **callback_kwargs)
  File "/home/vietnguyen/mysite/ecard/views.py", line 41, in edit_book
    return add_book(request)
  File "/home/vietnguyen/mysite/ecard/views.py", line 47, in add_book
    old_book = Book.objects.get(pk=jbook.get("id"))
  File "/usr/local/lib/python2.7/dist-packages/django/db/models/manager.py", line 127, in manager_method
    return getattr(self.get_queryset(), name)(*args, **kwargs)
  File "/usr/local/lib/python2.7/dist-packages/django/db/models/query.py", line 334, in get
    self.model._meta.object_name
DoesNotExist: Book matching query does not exist.
{"author":"Lois Lowry","comment":"Good story about the courage of the young girl during war. I learn something interesting about western history, nazi, war, etc..","iconUrl":"https://upload.wikimedia.org/wikipedia/en/2/23/Number_the_Stars_book_cover.jpeg","id":"5","link":"https://en.wikipedia.org/wiki/Number_the_Stars","mood":"Be Brave","name":"Number the Stars","vocabulary":"aaa,fiance,throne,herb,slap,trudge,scold,sabotage,stern,sputter or splutter,bellow,ponder,deftly,tug,bucket,frothy,wrinkle,meadow,dismay,attic,leap,dart,heap,snarl,leash"}
Internal Server Error: /ecard/edit_book/
Traceback (most recent call last):
  File "/usr/local/lib/python2.7/dist-packages/django/core/handlers/base.py", line 132, in get_response
    response = wrapped_callback(request, *callback_args, **callback_kwargs)
  File "/home/vietnguyen/mysite/ecard/views.py", line 41, in edit_book
    return add_book(request)
  File "/home/vietnguyen/mysite/ecard/views.py", line 49, in add_book
    link = old_book.link
AttributeError: 'Book' object has no attribute 'link'
{"author":"Lois Lowry","comment":"Good story about the courage of the young girl during war. I learn something interesting about western history, nazi, war, etc..","iconUrl":"https://upload.wikimedia.org/wikipedia/en/2/23/Number_the_Stars_book_cover.jpeg","id":"5","link":"https://en.wikipedia.org/wiki/Number_the_Stars","mood":"Be Brave","name":"Number the Stars","vocabulary":"aaee,aaa,fiance,throne,herb,slap,trudge,scold,sabotage,stern,sputter or splutter,bellow,ponder,deftly,tug,bucket,frothy,wrinkle,meadow,dismay,attic,leap,dart,heap,snarl,leash"}
{"author":"Louis Sachar","comment":"Really my first english book. I remember reading them with difficulty thanks to my bad english by then. I read it on my ipad.","iconUrl":"https://upload.wikimedia.org/wikipedia/en/c/c3/Sachar_-_Holes_Coverart.png","id":"1","link":"https://en.wikipedia.org/wiki/Holes_%28novel%29","mood":"Fate love kind child","name":"Holes","vocabulary":"now,shovel,lizard,crate,donkey,reptile,odor,onion,"}
{"author":"Louis Sachar","comment":"Really my first english book. I remember reading them with difficulty thanks to my bad english by then. I read it on my ipad.","iconUrl":"https://upload.wikimedia.org/wikipedia/en/c/c3/Sachar_-_Holes_Coverart.png","id":"1","link":"https://en.wikipedia.org/wiki/Holes_%28novel%29","mood":"Fate love kind child","name":"Holes","vocabulary":"now[go to drink now, lol],shovel,lizard,crate,donkey,reptile,odor,onion,"}
{"author":"Louis Sachar","comment":"Really my first english book. I remember reading them with difficulty thanks to my bad english by then. I read it on my ipad.","iconUrl":"https://upload.wikimedia.org/wikipedia/en/c/c3/Sachar_-_Holes_Coverart.png","id":"1","link":"https://en.wikipedia.org/wiki/Holes_%28novel%29","mood":"Fate love kind child","name":"Holes","vocabulary":"AAA,now[go to drink now, lol],shovel,lizard,crate,donkey,reptile,odor,onion,"}
{"author":"Louis Sachar","comment":"Really my first english book. I remember reading them with difficulty thanks to my bad english by then. I read it on my ipad.","iconUrl":"https://upload.wikimedia.org/wikipedia/en/c/c3/Sachar_-_Holes_Coverart.png","id":"1","link":"https://en.wikipedia.org/wiki/Holes_%28novel%29","mood":"Fate love kind child","name":"Holes","vocabulary":"AAA[phrase1],now[go to drink now, lol],shovel,lizard,crate,donkey,reptile,odor,onion,"}
{"author":"Louis Sachar","comment":"Really my first english book. I remember reading them with difficulty thanks to my bad english by then. I read it on my ipad.","iconUrl":"https://upload.wikimedia.org/wikipedia/en/c/c3/Sachar_-_Holes_Coverart.png","id":"1","link":"https://en.wikipedia.org/wiki/Holes_%28novel%29","mood":"Fate love kind child","name":"Holes","vocabulary":"AAA[phrase1],now[HAHA;go to drink now, lol],shovel,lizard,crate,donkey,reptile,odor,onion,"}
{"author":" Lois Lowry","comment":"Kira is a strong and talent girl despite her leg trouble. From amazon: \"As she did in The Giver and later Messenger, in Gathering Blue Lois Lowry challenges readers to imagine what our world could become, how people could evolve, and what could be considered valuable\"","iconUrl":"https://upload.wikimedia.org/wikipedia/en/9/98/Lowry_gathering_blue_cover.jpg","id":"2","link":"https://en.wikipedia.org/wiki/Gathering_Blue","mood":"Everyone is special","name":"Gathering Blue","vocabulary":"tend^^^^Weeds had gone untended while his wife had neared her time, given birth then died$$$$@@@@flourish@@@@agony@@@@weave@@@@dye@@@@defiant@@@@kettle@@@@mug@@@@ominous@@@@stalk"}
{"author":"Karen Cushman","comment":"wiki: Through the course of the book, Alyce transforms from a nameless, \"worthless\" nonentity into a young woman who has friends, skills, a name, a cat and a future.","iconUrl":"http://ecx.images-amazon.com/images/I/51XFr3yZg4L._SX334_BO1,204,203,200_.jpg","id":"3","link":"https://en.wikipedia.org/wiki/The_Midwife\u0027s_Apprentice","mood":"Life","name":"Midwife\u0027s Apprentice","vocabulary":"dung^^^^Something like Max\u0027s excrement :D$$$$@@@@midwife@@@@apprentice"}
{"author":"Karen Cushman","comment":"wiki: Through the course of the book, Alyce transforms from a nameless, \"worthless\" nonentity into a young woman who has friends, skills, a name, a cat and a future.","iconUrl":"http://ecx.images-amazon.com/images/I/51XFr3yZg4L._SX334_BO1,204,203,200_.jpg","id":"3","link":"https://en.wikipedia.org/wiki/The_Midwife\u0027s_Apprentice","mood":"Life","name":"Midwife\u0027s Apprentice","vocabulary":"dung^^^^Something like Max\u0027s excrement :D$$$$@@@@midwife@@@@apprentice"}
{"author":"Karen Cushman","comment":"wiki: Through the course of the book, Alyce transforms from a nameless, \"worthless\" nonentity into a young woman who has friends, skills, a name, a cat and a future.","iconUrl":"http://ecx.images-amazon.com/images/I/51XFr3yZg4L._SX334_BO1,204,203,200_.jpg","id":"3","link":"https://en.wikipedia.org/wiki/The_Midwife\u0027s_Apprentice","mood":"Life","name":"Midwife\u0027s Apprentice","vocabulary":"dung^^^^Something like Max\u0027s excrement :D$$$$@@@@midwife@@@@apprentice"}
{"author":"Lois Lowry","comment":"Good story about the courage of the young girl during war. I learn something interesting about western history, nazi, war, etc..","iconUrl":"https://upload.wikimedia.org/wikipedia/en/2/23/Number_the_Stars_book_cover.jpeg","id":"5","link":"https://en.wikipedia.org/wiki/Number_the_Stars","mood":"Be Brave","name":"Number the Stars","vocabulary":"fiance@@@@throne@@@@herb@@@@slap@@@@trudge@@@@scold@@@@sabotage@@@@stern@@@@sputter or splutter@@@@bellow@@@@ponder@@@@deftly@@@@tug@@@@bucket@@@@frothy@@@@wrinkle@@@@meadow@@@@dismay@@@@attic@@@@leap@@@@dart@@@@heap@@@@snarl@@@@leash"}
{"author":"Louis Sachar","comment":"Really my first english book. I remember reading them with difficulty thanks to my bad english by then. I read it on my ipad.","iconUrl":"https://upload.wikimedia.org/wikipedia/en/c/c3/Sachar_-_Holes_Coverart.png","id":"1","link":"https://en.wikipedia.org/wiki/Holes_%28novel%29","mood":"Fate love kind child","name":"Holes","vocabulary":"Test@@@@shovel@@@@lizard@@@@crate@@@@donkey@@@@reptile@@@@odor@@@@onion"}
