{"comment":"a","date":"2015-11-03 01:39:12+0000","description":"a","lastupdated":"2015-11-03 01:39:12+0000","name":"a","priority":1,"status":0,"id":7}
{"comment":"a","date":"2015-11-02 10:25:02+0000","description":"a","lastupdated":"2015-11-02 10:25:02+0000","name":"a","priority":1,"status":0,"id":0}
Internal Server Error: /ecard/edit_task/
Traceback (most recent call last):
  File "C:\Python27\lib\site-packages\django\core\handlers\base.py", line 132, in get_response
    response = wrapped_callback(request, *callback_args, **callback_kwargs)
  File "C:\Python27\mysite\ecard\views.py", line 69, in edit_task
    date = datetime.strptime(jtask.get('date'), "%Y-%m-%d %H:%M:%S")
  File "C:\Python27\lib\_strptime.py", line 328, in _strptime
    data_string[found.end():])
ValueError: unconverted data remains: +0000
{"comment":"a","date":"2015-11-03 01:39:12+0000","description":"a","lastupdated":"2015-11-03 01:39:12+0000","name":"a","priority":1,"status":0,"id":0}
Internal Server Error: /ecard/edit_task/
Traceback (most recent call last):
  File "C:\Python27\lib\site-packages\django\core\handlers\base.py", line 132, in get_response
    response = wrapped_callback(request, *callback_args, **callback_kwargs)
  File "C:\Python27\mysite\ecard\views.py", line 69, in edit_task
    date = datetime.strptime(jtask.get('date'), "%Y-%m-%d %H:%M:%S")
  File "C:\Python27\lib\_strptime.py", line 328, in _strptime
    data_string[found.end():])
ValueError: unconverted data remains: +0000
Not Found: /favicon.ico
{"comment":"a","date":"2015-11-02 10:25:02+0000","description":"a","lastupdated":"2015-11-02 10:25:02+0000","name":"a","priority":1,"status":0,"id":0}
Internal Server Error: /ecard/edit_task/
Traceback (most recent call last):
  File "C:\Python27\lib\site-packages\django\core\handlers\base.py", line 132, in get_response
    response = wrapped_callback(request, *callback_args, **callback_kwargs)
  File "C:\Python27\mysite\ecard\views.py", line 69, in edit_task
    date = datetime.strptime(jtask.get('date'), "%Y-%m-%d %H:%M:%S")
  File "C:\Python27\lib\_strptime.py", line 328, in _strptime
    data_string[found.end():])
ValueError: unconverted data remains: +0000
{"comment":"a","date":"2015-11-03 01:39:12+0000","description":"a","lastupdated":"2015-11-03 01:39:12+0000","name":"a","priority":1,"status":0,"id":0}
Internal Server Error: /ecard/edit_task/
Traceback (most recent call last):
  File "C:\Python27\lib\site-packages\django\core\handlers\base.py", line 132, in get_response
    response = wrapped_callback(request, *callback_args, **callback_kwargs)
  File "C:\Python27\mysite\ecard\views.py", line 69, in edit_task
    date = datetime.strptime(jtask.get('date'), "%Y-%m-%d %H:%M:%S")
  File "C:\Python27\lib\_strptime.py", line 328, in _strptime
    data_string[found.end():])
ValueError: unconverted data remains: +0000
Internal Server Error: /ecard/delete_task/
Traceback (most recent call last):
  File "C:\Python27\lib\site-packages\django\core\handlers\base.py", line 132, in get_response
    response = wrapped_callback(request, *callback_args, **callback_kwargs)
  File "C:\Python27\mysite\ecard\views.py", line 79, in delete_task
    deleted_task = Task.objects.get(pk=pk)
  File "C:\Python27\lib\site-packages\django\db\models\manager.py", line 127, in manager_method
    return getattr(self.get_queryset(), name)(*args, **kwargs)
  File "C:\Python27\lib\site-packages\django\db\models\query.py", line 334, in get
    self.model._meta.object_name
DoesNotExist: Task matching query does not exist.
{"comment":"a","date":"2015-11-03 01:39:12+0000","description":"a","lastupdated":"2015-11-03 01:39:12+0000","name":"a","priority":1,"status":0,"id":0}
Internal Server Error: /ecard/edit_task/
Traceback (most recent call last):
  File "C:\Python27\lib\site-packages\django\core\handlers\base.py", line 132, in get_response
    response = wrapped_callback(request, *callback_args, **callback_kwargs)
  File "C:\Python27\mysite\ecard\views.py", line 69, in edit_task
    date = datetime.strptime(jtask.get('date'), "%Y-%m-%d %H:%M:%S")
  File "C:\Python27\lib\_strptime.py", line 328, in _strptime
    data_string[found.end():])
ValueError: unconverted data remains: +0000
{"comment":"a","date":"2015-11-03 01:39:12+0000","description":"a","lastupdated":"2015-11-03 01:39:12+0000","name":"a","priority":1,"status":0,"id":0}
Internal Server Error: /ecard/edit_task/
Traceback (most recent call last):
  File "C:\Python27\lib\site-packages\django\core\handlers\base.py", line 132, in get_response
    response = wrapped_callback(request, *callback_args, **callback_kwargs)
  File "C:\Python27\mysite\ecard\views.py", line 70, in edit_task
    last_update= datetime.strptime(jtask.get('lastupdated'), "%Y-%m-%d %H:%M:%S")
  File "C:\Python27\lib\_strptime.py", line 328, in _strptime
    data_string[found.end():])
ValueError: unconverted data remains: +0000
{"comment":"a","date":"2015-11-03 01:39:12+0000","description":"a","lastupdated":"2015-11-03 01:39:12+0000","name":"a","priority":1,"status":0,"id":0}
Internal Server Error: /ecard/edit_task/
Traceback (most recent call last):
  File "C:\Python27\lib\site-packages\django\core\handlers\base.py", line 132, in get_response
    response = wrapped_callback(request, *callback_args, **callback_kwargs)
  File "C:\Python27\mysite\ecard\views.py", line 70, in edit_task
    last_update= datetime.strptime(jtask.get('lastupdated'), "%Y-%m-%d %H:%M:%S")
  File "C:\Python27\lib\_strptime.py", line 328, in _strptime
    data_string[found.end():])
ValueError: unconverted data remains: +0000
{"comment":"a","date":"2015-11-03 01:39:12+0000","description":"a","lastupdated":"2015-11-03 01:39:12+0000","name":"a","priority":1,"status":0,"id":0}
Internal Server Error: /ecard/edit_task/
Traceback (most recent call last):
  File "C:\Python27\lib\site-packages\django\core\handlers\base.py", line 132, in get_response
    response = wrapped_callback(request, *callback_args, **callback_kwargs)
  File "C:\Python27\mysite\ecard\views.py", line 70, in edit_task
    last_update= datetime.strptime(jtask.get('lastupdated'), "%Y-%m-%d %H:%M:%S")
  File "C:\Python27\lib\_strptime.py", line 328, in _strptime
    data_string[found.end():])
ValueError: unconverted data remains: +0000
{"comment":"a","date":"2015-11-03 01:39:12+0000","description":"a","lastupdated":"2015-11-03 01:39:12+0000","name":"a","priority":1,"status":0,"id":0}
Internal Server Error: /ecard/edit_task/
Traceback (most recent call last):
  File "C:\Python27\lib\site-packages\django\core\handlers\base.py", line 132, in get_response
    response = wrapped_callback(request, *callback_args, **callback_kwargs)
  File "C:\Python27\mysite\ecard\views.py", line 70, in edit_task
    last_update= datetime.strptime(jtask.get('lastupdated'), "%Y-%m-%d %H:%M:%S")
  File "C:\Python27\lib\_strptime.py", line 328, in _strptime
    data_string[found.end():])
ValueError: unconverted data remains: +0000
Internal Server Error: /ecard/delete_task/
Traceback (most recent call last):
  File "C:\Python27\lib\site-packages\django\core\handlers\base.py", line 132, in get_response
    response = wrapped_callback(request, *callback_args, **callback_kwargs)
  File "C:\Python27\mysite\ecard\views.py", line 79, in delete_task
    deleted_task = Task.objects.get(pk=pk)
  File "C:\Python27\lib\site-packages\django\db\models\manager.py", line 127, in manager_method
    return getattr(self.get_queryset(), name)(*args, **kwargs)
  File "C:\Python27\lib\site-packages\django\db\models\query.py", line 334, in get
    self.model._meta.object_name
DoesNotExist: Task matching query does not exist.
{"date":"2015-11-02 08:54:05+0000","description":"Go home early, it\u0027s Monday. Working late on the first day of week can lead into really hard week","lastupdated":"2015-11-02 08:54:08+0000","name":"Go home early","priority":2,"status":1,"id":2}
{"date":"2015-11-02 08:54:05+0000","description":"Go home early, it\u0027s Monday. Working late on the first day of week can lead into really hard week","lastupdated":"2015-11-02 08:54:08+0000","name":"Go home early","priority":2,"status":1,"id":3}
Internal Server Error: /ecard/delete_task/
Traceback (most recent call last):
  File "C:\Python27\lib\site-packages\django\core\handlers\base.py", line 132, in get_response
    response = wrapped_callback(request, *callback_args, **callback_kwargs)
  File "C:\Python27\mysite\ecard\views.py", line 79, in delete_task
    deleted_task = Task.objects.get(pk=pk)
  File "C:\Python27\lib\site-packages\django\db\models\manager.py", line 127, in manager_method
    return getattr(self.get_queryset(), name)(*args, **kwargs)
  File "C:\Python27\lib\site-packages\django\db\models\query.py", line 334, in get
    self.model._meta.object_name
DoesNotExist: Task matching query does not exist.
{"date":"2015-11-02 08:55:42+0000","description":"Try to eat healthy food, walking around, drink enough water","lastupdated":"2015-11-02 08:55:42+0000","name":"Be healthy and beautiful","priority":3,"status":1,"id":1}
{"date":"2015-11-02 08:55:42+0000","description":"Try to eat healthy food, walking around, drink enough water","lastupdated":"2015-11-02 08:55:42+0000","name":"Be healthy and beautiful","priority":3,"status":0,"id":10}
{"date":"2015-11-02 08:54:05+0000","description":"Go home early, it\u0027s Monday. Working late on the first day of week can lead into really hard week","lastupdated":"2015-11-02 08:54:08+0000","name":"Go home early","priority":2,"status":0,"id":11}
{"date":"2015-11-02 08:54:05+0000","description":"Go home early, it\u0027s Monday. Working late on the first day of week can lead into really hard week","lastupdated":"2015-11-02 08:54:08+0000","name":"Go home early","priority":2,"status":1,"id":17}
{"comment":"a","date":"2015-11-03 08:29:17+0000","description":"a","lastupdated":"2015-11-03 08:29:17+0000","name":"a","priority":1,"status":0,"id":21}
{"comment":"a","date":"2015-11-03 08:29:17+0000","description":"a","lastupdated":"2015-11-03 08:29:17+0000","name":"a","priority":1,"status":0,"id":0}
Internal Server Error: /ecard/edit_task/
Traceback (most recent call last):
  File "C:\Python27\lib\site-packages\django\core\handlers\base.py", line 132, in get_response
    response = wrapped_callback(request, *callback_args, **callback_kwargs)
  File "C:\Python27\mysite\ecard\views.py", line 72, in edit_task
    new_task.save()
  File "C:\Python27\lib\site-packages\django\db\models\base.py", line 734, in save
    force_update=force_update, update_fields=update_fields)
  File "C:\Python27\lib\site-packages\django\db\models\base.py", line 762, in save_base
    updated = self._save_table(raw, cls, force_insert, force_update, using, update_fields)
  File "C:\Python27\lib\site-packages\django\db\models\base.py", line 846, in _save_table
    result = self._do_insert(cls._base_manager, using, fields, update_pk, raw)
  File "C:\Python27\lib\site-packages\django\db\models\base.py", line 885, in _do_insert
    using=using, raw=raw)
  File "C:\Python27\lib\site-packages\django\db\models\manager.py", line 127, in manager_method
    return getattr(self.get_queryset(), name)(*args, **kwargs)
  File "C:\Python27\lib\site-packages\django\db\models\query.py", line 920, in _insert
    return query.get_compiler(using=using).execute_sql(return_id)
  File "C:\Python27\lib\site-packages\django\db\models\sql\compiler.py", line 973, in execute_sql
    for sql, params in self.as_sql():
  File "C:\Python27\lib\site-packages\django\db\models\sql\compiler.py", line 931, in as_sql
    for obj in self.query.objs
  File "C:\Python27\lib\site-packages\django\db\models\fields\__init__.py", line 710, in get_db_prep_save
    prepared=False)
  File "C:\Python27\lib\site-packages\django\db\models\fields\__init__.py", line 978, in get_db_prep_value
    value = connection.ops.validate_autopk_value(value)
  File "C:\Python27\lib\site-packages\django\db\backends\mysql\operations.py", line 137, in validate_autopk_value
    raise ValueError('The database backend does not accept 0 as a '
ValueError: The database backend does not accept 0 as a value for AutoField.
{"date":"2015-11-03 08:29:17+0000","description":"a","lastupdated":"2015-11-03 08:29:17+0000","name":"a","priority":1,"status":1,"id":24}
{"comment":"a","date":"2015-11-03 08:29:17+0000","description":"a","lastupdated":"2015-11-03 08:29:17+0000","name":"a","priority":1,"status":0,"id":0}
Internal Server Error: /ecard/edit_task/
Traceback (most recent call last):
  File "C:\Python27\lib\site-packages\django\core\handlers\base.py", line 132, in get_response
    response = wrapped_callback(request, *callback_args, **callback_kwargs)
  File "C:\Python27\mysite\ecard\views.py", line 72, in edit_task
    new_task.save()
  File "C:\Python27\lib\site-packages\django\db\models\base.py", line 734, in save
    force_update=force_update, update_fields=update_fields)
  File "C:\Python27\lib\site-packages\django\db\models\base.py", line 762, in save_base
    updated = self._save_table(raw, cls, force_insert, force_update, using, update_fields)
  File "C:\Python27\lib\site-packages\django\db\models\base.py", line 846, in _save_table
    result = self._do_insert(cls._base_manager, using, fields, update_pk, raw)
  File "C:\Python27\lib\site-packages\django\db\models\base.py", line 885, in _do_insert
    using=using, raw=raw)
  File "C:\Python27\lib\site-packages\django\db\models\manager.py", line 127, in manager_method
    return getattr(self.get_queryset(), name)(*args, **kwargs)
  File "C:\Python27\lib\site-packages\django\db\models\query.py", line 920, in _insert
    return query.get_compiler(using=using).execute_sql(return_id)
  File "C:\Python27\lib\site-packages\django\db\models\sql\compiler.py", line 973, in execute_sql
    for sql, params in self.as_sql():
  File "C:\Python27\lib\site-packages\django\db\models\sql\compiler.py", line 931, in as_sql
    for obj in self.query.objs
  File "C:\Python27\lib\site-packages\django\db\models\fields\__init__.py", line 710, in get_db_prep_save
    prepared=False)
  File "C:\Python27\lib\site-packages\django\db\models\fields\__init__.py", line 978, in get_db_prep_value
    value = connection.ops.validate_autopk_value(value)
  File "C:\Python27\lib\site-packages\django\db\backends\mysql\operations.py", line 137, in validate_autopk_value
    raise ValueError('The database backend does not accept 0 as a '
ValueError: The database backend does not accept 0 as a value for AutoField.
{"comment":"a","date":"2015-11-03 08:29:17+0000","description":"a","lastupdated":"2015-11-03 08:29:17+0000","name":"a","priority":1,"status":1,"id":21}
{"comment":"a","date":"2015-11-03 08:29:17+0000","description":"a","lastupdated":"2015-11-03 08:29:17+0000","name":"a","priority":1,"status":1,"id":0}
Internal Server Error: /ecard/edit_task/
Traceback (most recent call last):
  File "C:\Python27\lib\site-packages\django\core\handlers\base.py", line 132, in get_response
    response = wrapped_callback(request, *callback_args, **callback_kwargs)
  File "C:\Python27\mysite\ecard\views.py", line 72, in edit_task
    new_task.save()
  File "C:\Python27\lib\site-packages\django\db\models\base.py", line 734, in save
    force_update=force_update, update_fields=update_fields)
  File "C:\Python27\lib\site-packages\django\db\models\base.py", line 762, in save_base
    updated = self._save_table(raw, cls, force_insert, force_update, using, update_fields)
  File "C:\Python27\lib\site-packages\django\db\models\base.py", line 846, in _save_table
    result = self._do_insert(cls._base_manager, using, fields, update_pk, raw)
  File "C:\Python27\lib\site-packages\django\db\models\base.py", line 885, in _do_insert
    using=using, raw=raw)
  File "C:\Python27\lib\site-packages\django\db\models\manager.py", line 127, in manager_method
    return getattr(self.get_queryset(), name)(*args, **kwargs)
  File "C:\Python27\lib\site-packages\django\db\models\query.py", line 920, in _insert
    return query.get_compiler(using=using).execute_sql(return_id)
  File "C:\Python27\lib\site-packages\django\db\models\sql\compiler.py", line 973, in execute_sql
    for sql, params in self.as_sql():
  File "C:\Python27\lib\site-packages\django\db\models\sql\compiler.py", line 931, in as_sql
    for obj in self.query.objs
  File "C:\Python27\lib\site-packages\django\db\models\fields\__init__.py", line 710, in get_db_prep_save
    prepared=False)
  File "C:\Python27\lib\site-packages\django\db\models\fields\__init__.py", line 978, in get_db_prep_value
    value = connection.ops.validate_autopk_value(value)
  File "C:\Python27\lib\site-packages\django\db\backends\mysql\operations.py", line 137, in validate_autopk_value
    raise ValueError('The database backend does not accept 0 as a '
ValueError: The database backend does not accept 0 as a value for AutoField.
{"date":"2015-11-03 08:29:17+0000","description":"a","lastupdated":"2015-11-03 08:29:17+0000","name":"a","priority":1,"status":0,"id":24}
{"comment":"a","date":"2015-11-03 08:29:17+0000","description":"a","lastupdated":"2015-11-03 08:29:17+0000","name":"a","priority":1,"status":1,"id":0}
Internal Server Error: /ecard/edit_task/
Traceback (most recent call last):
  File "C:\Python27\lib\site-packages\django\core\handlers\base.py", line 132, in get_response
    response = wrapped_callback(request, *callback_args, **callback_kwargs)
  File "C:\Python27\mysite\ecard\views.py", line 72, in edit_task
    new_task.save()
  File "C:\Python27\lib\site-packages\django\db\models\base.py", line 734, in save
    force_update=force_update, update_fields=update_fields)
  File "C:\Python27\lib\site-packages\django\db\models\base.py", line 762, in save_base
    updated = self._save_table(raw, cls, force_insert, force_update, using, update_fields)
  File "C:\Python27\lib\site-packages\django\db\models\base.py", line 846, in _save_table
    result = self._do_insert(cls._base_manager, using, fields, update_pk, raw)
  File "C:\Python27\lib\site-packages\django\db\models\base.py", line 885, in _do_insert
    using=using, raw=raw)
  File "C:\Python27\lib\site-packages\django\db\models\manager.py", line 127, in manager_method
    return getattr(self.get_queryset(), name)(*args, **kwargs)
  File "C:\Python27\lib\site-packages\django\db\models\query.py", line 920, in _insert
    return query.get_compiler(using=using).execute_sql(return_id)
  File "C:\Python27\lib\site-packages\django\db\models\sql\compiler.py", line 973, in execute_sql
    for sql, params in self.as_sql():
  File "C:\Python27\lib\site-packages\django\db\models\sql\compiler.py", line 931, in as_sql
    for obj in self.query.objs
  File "C:\Python27\lib\site-packages\django\db\models\fields\__init__.py", line 710, in get_db_prep_save
    prepared=False)
  File "C:\Python27\lib\site-packages\django\db\models\fields\__init__.py", line 978, in get_db_prep_value
    value = connection.ops.validate_autopk_value(value)
  File "C:\Python27\lib\site-packages\django\db\backends\mysql\operations.py", line 137, in validate_autopk_value
    raise ValueError('The database backend does not accept 0 as a '
ValueError: The database backend does not accept 0 as a value for AutoField.
{"date":"2015-11-03 08:29:17+0000","description":"a","lastupdated":"2015-11-03 08:29:17+0000","name":"a","priority":1,"status":1,"id":24}
{"comment":"a","date":"2015-11-03 08:29:17+0000","description":"a","lastupdated":"2015-11-03 08:29:17+0000","name":"a","priority":1,"status":1,"id":0}
Internal Server Error: /ecard/edit_task/
Traceback (most recent call last):
  File "C:\Python27\lib\site-packages\django\core\handlers\base.py", line 132, in get_response
    response = wrapped_callback(request, *callback_args, **callback_kwargs)
  File "C:\Python27\mysite\ecard\views.py", line 72, in edit_task
    new_task.save()
  File "C:\Python27\lib\site-packages\django\db\models\base.py", line 734, in save
    force_update=force_update, update_fields=update_fields)
  File "C:\Python27\lib\site-packages\django\db\models\base.py", line 762, in save_base
    updated = self._save_table(raw, cls, force_insert, force_update, using, update_fields)
  File "C:\Python27\lib\site-packages\django\db\models\base.py", line 846, in _save_table
    result = self._do_insert(cls._base_manager, using, fields, update_pk, raw)
  File "C:\Python27\lib\site-packages\django\db\models\base.py", line 885, in _do_insert
    using=using, raw=raw)
  File "C:\Python27\lib\site-packages\django\db\models\manager.py", line 127, in manager_method
    return getattr(self.get_queryset(), name)(*args, **kwargs)
  File "C:\Python27\lib\site-packages\django\db\models\query.py", line 920, in _insert
    return query.get_compiler(using=using).execute_sql(return_id)
  File "C:\Python27\lib\site-packages\django\db\models\sql\compiler.py", line 973, in execute_sql
    for sql, params in self.as_sql():
  File "C:\Python27\lib\site-packages\django\db\models\sql\compiler.py", line 931, in as_sql
    for obj in self.query.objs
  File "C:\Python27\lib\site-packages\django\db\models\fields\__init__.py", line 710, in get_db_prep_save
    prepared=False)
  File "C:\Python27\lib\site-packages\django\db\models\fields\__init__.py", line 978, in get_db_prep_value
    value = connection.ops.validate_autopk_value(value)
  File "C:\Python27\lib\site-packages\django\db\backends\mysql\operations.py", line 137, in validate_autopk_value
    raise ValueError('The database backend does not accept 0 as a '
ValueError: The database backend does not accept 0 as a value for AutoField.
{"comment":"b","date":"2015-11-03 08:30:18+0000","description":"b","lastupdated":"2015-11-03 08:30:18+0000","name":"b","priority":1,"status":0,"id":34}
{"comment":"a","date":"2015-11-03 08:29:17+0000","description":"a","lastupdated":"2015-11-03 08:29:17+0000","name":"a","priority":1,"status":1,"id":0}
Internal Server Error: /ecard/edit_task/
Traceback (most recent call last):
  File "C:\Python27\lib\site-packages\django\core\handlers\base.py", line 132, in get_response
    response = wrapped_callback(request, *callback_args, **callback_kwargs)
  File "C:\Python27\mysite\ecard\views.py", line 72, in edit_task
    new_task.save()
  File "C:\Python27\lib\site-packages\django\db\models\base.py", line 734, in save
    force_update=force_update, update_fields=update_fields)
  File "C:\Python27\lib\site-packages\django\db\models\base.py", line 762, in save_base
    updated = self._save_table(raw, cls, force_insert, force_update, using, update_fields)
  File "C:\Python27\lib\site-packages\django\db\models\base.py", line 846, in _save_table
    result = self._do_insert(cls._base_manager, using, fields, update_pk, raw)
  File "C:\Python27\lib\site-packages\django\db\models\base.py", line 885, in _do_insert
    using=using, raw=raw)
  File "C:\Python27\lib\site-packages\django\db\models\manager.py", line 127, in manager_method
    return getattr(self.get_queryset(), name)(*args, **kwargs)
  File "C:\Python27\lib\site-packages\django\db\models\query.py", line 920, in _insert
    return query.get_compiler(using=using).execute_sql(return_id)
  File "C:\Python27\lib\site-packages\django\db\models\sql\compiler.py", line 973, in execute_sql
    for sql, params in self.as_sql():
  File "C:\Python27\lib\site-packages\django\db\models\sql\compiler.py", line 931, in as_sql
    for obj in self.query.objs
  File "C:\Python27\lib\site-packages\django\db\models\fields\__init__.py", line 710, in get_db_prep_save
    prepared=False)
  File "C:\Python27\lib\site-packages\django\db\models\fields\__init__.py", line 978, in get_db_prep_value
    value = connection.ops.validate_autopk_value(value)
  File "C:\Python27\lib\site-packages\django\db\backends\mysql\operations.py", line 137, in validate_autopk_value
    raise ValueError('The database backend does not accept 0 as a '
ValueError: The database backend does not accept 0 as a value for AutoField.
{"comment":"b","date":"2015-11-03 08:30:18+0000","description":"b","lastupdated":"2015-11-03 08:30:18+0000","name":"b","priority":1,"status":0,"id":0}
Internal Server Error: /ecard/edit_task/
Traceback (most recent call last):
  File "C:\Python27\lib\site-packages\django\core\handlers\base.py", line 132, in get_response
    response = wrapped_callback(request, *callback_args, **callback_kwargs)
  File "C:\Python27\mysite\ecard\views.py", line 72, in edit_task
    new_task.save()
  File "C:\Python27\lib\site-packages\django\db\models\base.py", line 734, in save
    force_update=force_update, update_fields=update_fields)
  File "C:\Python27\lib\site-packages\django\db\models\base.py", line 762, in save_base
    updated = self._save_table(raw, cls, force_insert, force_update, using, update_fields)
  File "C:\Python27\lib\site-packages\django\db\models\base.py", line 846, in _save_table
    result = self._do_insert(cls._base_manager, using, fields, update_pk, raw)
  File "C:\Python27\lib\site-packages\django\db\models\base.py", line 885, in _do_insert
    using=using, raw=raw)
  File "C:\Python27\lib\site-packages\django\db\models\manager.py", line 127, in manager_method
    return getattr(self.get_queryset(), name)(*args, **kwargs)
  File "C:\Python27\lib\site-packages\django\db\models\query.py", line 920, in _insert
    return query.get_compiler(using=using).execute_sql(return_id)
  File "C:\Python27\lib\site-packages\django\db\models\sql\compiler.py", line 973, in execute_sql
    for sql, params in self.as_sql():
  File "C:\Python27\lib\site-packages\django\db\models\sql\compiler.py", line 931, in as_sql
    for obj in self.query.objs
  File "C:\Python27\lib\site-packages\django\db\models\fields\__init__.py", line 710, in get_db_prep_save
    prepared=False)
  File "C:\Python27\lib\site-packages\django\db\models\fields\__init__.py", line 978, in get_db_prep_value
    value = connection.ops.validate_autopk_value(value)
  File "C:\Python27\lib\site-packages\django\db\backends\mysql\operations.py", line 137, in validate_autopk_value
    raise ValueError('The database backend does not accept 0 as a '
ValueError: The database backend does not accept 0 as a value for AutoField.
{"comment":"a","date":"2015-11-04 08:33:44+0000","description":"a","lastupdated":"2015-11-04 08:33:44+0000","name":"a","priority":1,"status":0,"id":38}
{"comment":"vvv","date":"2015-11-05 08:36:12+0000","description":"vvv","lastupdated":"2015-11-05 08:36:12+0000","name":"vvv","priority":1,"status":0,"id":40}
{"comment":"xxxxxx","date":"2015-11-06 08:43:50+0000","description":"xxxxxx","lastupdated":"2015-11-06 08:43:50+0000","name":"xxxxxx","priority":1,"status":0,"id":42}
{"comment":"a","date":"2015-11-03 08:46:44+0000","description":"a","lastupdated":"2015-11-03 08:46:44+0000","name":"a","priority":1,"status":0,"id":1}
{"comment":"a","date":"2015-11-03 08:53:34+0000","description":"a","lastupdated":"2015-11-03 08:53:34+0000","name":"a","priority":1,"status":0,"id":1}
{"comment":"a","date":"2015-11-03 08:58:56+0000","description":"a","lastupdated":"2015-11-03 08:58:56+0000","name":"a","priority":1,"status":0,"id":1}
{"comment":"la la la","date":"2015-11-04 04:31:18+0000","description":"I love my house","lastupdated":"2015-11-04 04:31:18+0000","name":"Go home early","priority":1,"status":0}
{"date":"2015-11-04 04:31:18+0000","description":"I love my house","id":"2","lastupdated":"2015-11-04 04:31:18+0000","name":"Go home early","priority":1,"status":1}
{"date":"2015-11-04 04:31:18+0000","description":"I love my house","id":"2","lastupdated":"2015-11-04 04:31:18+0000","name":"Go home early","priority":1,"status":1}
Not Found: /favicon.ico
{"date":"2015-11-04 04:31:18+0000","description":"I love my house","id":"2","lastupdated":"2015-11-04 04:31:18+0000","name":"Go home early","priority":1,"status":1}
{"date":"2015-11-04 04:31:18+0000","description":"I love my house","id":"3","lastupdated":"2015-11-04 04:31:18+0000","name":"Go home early","priority":1,"status":0}
{"comment":"","date":"2015-11-03 08:58:56+0000","description":"haha","id":"1","lastupdated":"2015-11-03 08:58:56+0000","name":"wtf","priority":1,"status":0}
{"date":"2015-11-03 08:58:56+0000","description":"haha","id":"1","lastupdated":"2015-11-03 08:58:56+0000","name":"wtf","priority":1,"status":1}
